Workbook

Sheet Sunday WK1 (1)
B1: Freight | C1: Grocery | E1: Meat | F1: Bakery | G1: Bake off | H1: Deli | I1: Produce | J1: Produce Shrink | K1: Dairy | L1: Pharmacy | M1: Receiving Totals | N1: Total
B2: Name: | C2: =1-E2-F2-G2-H2-I2-J2-K2-L2 -> 0.478 | E2: 0.099 | F2: 0 | G2: 0 | H2: 0 | I2: 0.159 | J2: 0.122 | K2: 0.142 | L2: 0 | N2: =SUM(C2:M2) -> 1
B3: SHANNON | C3: =C2*$N$3 -> 123.79722 | E3: =E2*$N$3 -> 25.64001 | F3: =F2*$N$3 -> 0 | G3: =G2*$N$3 -> 0 | H3: =H2*$N$3 -> 0 | I3: =I2*$N$3 -> 41.17941 | J3: =J2*$N$3 -> 31.59678 | K3: =K2*$N$3 -> 36.77658 | L3: =L2*$N$3 -> 0 | N3: 258.99
A4: Receiving Date: | B4: 46194
A5: Invoice Number | B5: Supplier Name | C5: Grocery Purchases | D5: Tobacco Purchases | E5: Meat Purchases | F5: Bakery Purchases | G5: Bakery In Store | H5: Deli Purchases | I5: Produce Purchases | J5: Produce Shrink | K5: Dairy Purchases | L5: Pharmacy Purchases | M5: GST | N5: Total Invoice**
A6: 126281 | B6: ITALIAN BAKERY | C6: =N6-D6-E6-F6-G6-H6-I6-J6-K6-L6-M6-D60-E60-F60-G60-H60-I60-J60-K60-L60-C60 -> 246.09 | N6: 246.09
A7: 4003652120 | B7: SAPUTO DAIRY PRODUCTS | C7: =N7-D7-E7-F7-G7-H7-I7-J7-K7-L7-M7-D61-E61-F61-G61-H61-I61-J61-K61-L61-C61 -> 1.8207658e-14 | K7: 2699.31 | M7: 0.48 | N7: 2699.79
A8: SO185613 | B8: STAR PRODUCE | C8: =N8-D8-E8-F8-G8-H8-I8-J8-K8-L8-M8-D62-E62-F62-G62-H62-I62-J62-K62-L62-C62 -> -1.7763568e-15 | I8: 250.1 | M8: 8.97 | N8: 259.07
A9: 771176 | B9: PACIFIC FRESH FISH | C9: =N9-D9-E9-F9-G9-H9-I9-J9-K9-L9-M9-D63-E63-F63-G63-H63-I63-J63-K63-L63-C63 -> 93 | N9: 93
A10: 3278879 | B10: LILYDALE SOFINA FOODS | C10: =N10-D10-E10-F10-G10-H10-I10-J10-K10-L10-M10-D64-E64-F64-G64-H64-I64-J64-K64-L64-C64 -> 0 | E10: 47.02 | N10: 47.02
A11: 6644176 | B11: THE GROCERY PEOPLE | C11: =N11-D11-E11-F11-G11-H11-I11-J11-K11-L11-M11-D65-E65-F65-G65-H65-I65-J65-K65-L65-C65 -> 0 | E11: 2034.75 | N11: 2034.75
A12: 6644717 | B12: THE GROCERY PEOPLE | C12: =N12-D12-E12-F12-G12-H12-I12-J12-K12-L12-M12-D66-E66-F66-G66-H66-I66-J66-K66-L66-C66 -> 0 | E12: 436.05 | N12: 436.05
A13: 6647609 | B13: THE GROCERY PEOPLE | C13: =N13-D13-E13-F13-G13-H13-I13-J13-K13-L13-M13-D67-E67-F67-G67-H67-I67-J67-K67-L67-C67 -> 61.72 | N13: 61.72
A14: 6644304 | B14: THE GROCERY PEOPLE | C14: =N14-D14-E14-F14-G14-H14-I14-J14-K14-L14-M14-D68-E68-F68-G68-H68-I68-J68-K68-L68-C68 -> 148.32 | N14: 148.32
A15: 6644306 | B15: THE GROCERY PEOPLE | C15: =N15-D15-E15-F15-G15-H15-I15-J15-K15-L15-M15-D69-E69-F69-G69-H69-I69-J69-K69-L69-C69 -> 552.57 | N15: 552.57
A16: 6645036 | B16: THE GROCERY PEOPLE | C16: =N16-D16-E16-F16-G16-H16-I16-J16-K16-L16-M16-D70-E70-F70-G70-H70-I70-J70-K70-L70-C70 -> 0 | N16: 101.34 | O16: MEAT SUPPLIES - DIGI SCALE LABELS
A17: 6445919 | B17: THE GROCERY PEOPLE | C17: =N17-D17-E17-F17-G17-H17-I17-J17-K17-L17-M17-D71-E71-F71-G71-H71-I71-J71-K71-L71-C71 -> 325.68 | N17: 325.68
A18: 6646756 | B18: THE GROCERY PEOPLE | C18: =N18-D18-E18-F18-G18-H18-I18-J18-K18-L18-M18-D72-E72-F72-G72-H72-I72-J72-K72-L72-C72 -> 0 | E18: 73.59 | N18: 73.59
A19: 6646757 | B19: THE GROCERY PEOPLE | C19: =N19-D19-E19-F19-G19-H19-I19-J19-K19-L19-M19-D73-E73-F73-G73-H73-I73-J73-K73-L73-C73 -> 0 | E19: 61.66 | N19: 61.66
A20: 6647235 | B20: THE GROCERY PEOPLE | C20: =N20-D20-E20-F20-G20-H20-I20-J20-K20-L20-M20-D74-E74-F74-G74-H74-I74-J74-K74-L74-C74 -> 422.16 | N20: 422.16
A21: 6650196 | B21: THE GROCERY PEOPLE | C21: =N21-D21-E21-F21-G21-H21-I21-J21-K21-L21-M21-D75-E75-F75-G75-H75-I75-J75-K75-L75-C75 -> 0 | K21: 36.37 | N21: 36.37
A22: 6650197 | B22: THE GROCERY PEOPLE | C22: =N22-D22-E22-F22-G22-H22-I22-J22-K22-L22-M22-D76-E76-F76-G76-H76-I76-J76-K76-L76-C76 -> 0 | K22: 17.67 | N22: 17.67
A23: 5624761 | B23: THE GROCERY PEOPLE | C23: =N23-D23-E23-F23-G23-H23-I23-J23-K23-L23-M23-D77-E77-F77-G77-H77-I77-J77-K77-L77-C77 -> 152.44 | N23: 152.44
A24: 5625509 | B24: THE GROCERY PEOPLE | C24: =N24-D24-E24-F24-G24-H24-I24-J24-K24-L24-M24-D78-E78-F78-G78-H78-I78-J78-K78-L78-C78 -> 127.22 | N24: 127.22
A25: 5626052 | B25: THE GROCERY PEOPLE | C25: =N25-D25-E25-F25-G25-H25-I25-J25-K25-L25-M25-D79-E79-F79-G79-H79-I79-J79-K79-L79-C79 -> 0 | N25: 351.91 | O25: MEAT SUPPLIES - FOAM TRAYS, STRETCH FILM
A26: 5626479 | B26: THE GROCERY PEOPLE | C26: =N26-D26-E26-F26-G26-H26-I26-J26-K26-L26-M26-D80-E80-F80-G80-H80-I80-J80-K80-L80-C80 -> 168.81 | N26: 168.81
A27: 5626709 | B27: THE GROCERY PEOPLE | C27: =N27-D27-E27-F27-G27-H27-I27-J27-K27-L27-M27-D81-E81-F81-G81-H81-I81-J81-K81-L81-C81 -> 2333.06 | N27: 2333.06
A28: 5627364 | B28: THE GROCERY PEOPLE | C28: =N28-D28-E28-F28-G28-H28-I28-J28-K28-L28-M28-D82-E82-F82-G82-H82-I82-J82-K82-L82-C82 -> 1780.41 | N28: 1780.41
A29: 5627676 | B29: THE GROCERY PEOPLE | C29: =N29-D29-E29-F29-G29-H29-I29-J29-K29-L29-M29-D83-E83-F83-G83-H83-I83-J83-K83-L83-C83 -> 0 | K29: 1265.91 | N29: 1265.91
A30: 5628111 | B30: THE GROCERY PEOPLE | C30: =N30-D30-E30-F30-G30-H30-I30-J30-K30-L30-M30-D84-E84-F84-G84-H84-I84-J84-K84-L84-C84 -> 14120.7 | N30: 14120.7
A31: 8239352 | B31: THE GROCERY PEOPLE | C31: =N31-D31-E31-F31-G31-H31-I31-J31-K31-L31-M31-D85-E85-F85-G85-H85-I85-J85-K85-L85-C85 -> 0 | E31: 764.27 | N31: 764.27
A32: 8239683 | B32: THE GROCERY PEOPLE | C32: =N32-D32-E32-F32-G32-H32-I32-J32-K32-L32-M32-D86-E86-F86-G86-H86-I86-J86-K86-L86-C86 -> 0 | E32: 974.51 | N32: 974.51
A33: 5624975 | B33: THE GROCERY PEOPLE | C33: =N33-D33-E33-F33-G33-H33-I33-J33-K33-L33-M33-D87-E87-F87-G87-H87-I87-J87-K87-L87-C87 -> 5578.24 | N33: 5578.24
A34: 5625079 | B34: THE GROCERY PEOPLE | C34: =N34-D34-E34-F34-G34-H34-I34-J34-K34-L34-M34-D88-E88-F88-G88-H88-I88-J88-K88-L88-C88 -> 5077.32 | N34: 5077.32
A35: 5627277 | B35: THE GROCERY PEOPLE | C35: =N35-D35-E35-F35-G35-H35-I35-J35-K35-L35-M35-D89-E89-F89-G89-H89-I89-J89-K89-L89-C89 -> 152.44 | E35: 1833.49 | N35: 1985.93
A36: 5627365 | B36: THE GROCERY PEOPLE | C36: =N36-D36-E36-F36-G36-H36-I36-J36-K36-L36-M36-D90-E90-F90-G90-H90-I90-J90-K90-L90-C90 -> 0 | E36: 459.9 | N36: 459.9
A37: 5624976 | B37: THE GROCERY PEOPLE | C37: =N37-D37-E37-F37-G37-H37-I37-J37-K37-L37-M37-D91-E91-F91-G91-H91-I91-J91-K91-L91-C91 -> 1776.7 | N37: 1776.7
A38: 5627404 | B38: THE GROCERY PEOPLE | C38: =N38-D38-E38-F38-G38-H38-I38-J38-K38-L38-M38-D92-E92-F92-G92-H92-I92-J92-K92-L92-C92 -> 43.02 | N38: 43.02
A39: 5627560 | B39: THE GROCERY PEOPLE | C39: =N39-D39-E39-F39-G39-H39-I39-J39-K39-L39-M39-D93-E93-F93-G93-H93-I93-J93-K93-L93-C93 -> 829.78 | E39: 364.59 | N39: 1194.37
A40: 5627677 | B40: THE GROCERY PEOPLE | C40: =N40-D40-E40-F40-G40-H40-I40-J40-K40-L40-M40-D94-E94-F94-G94-H94-I94-J94-K94-L94-C94 -> 0 | K40: 534.04 | N40: 534.04
...

Sheet Monday WK1 (2)
B1: Freight | C1: Grocery | E1: Meat | F1: Bakery | G1: Bake off | H1: Deli | I1: Produce | J1: Produce Shrink | K1: Dairy | L1: Pharmacy | M1: Receiving Totals | N1: Total
B2: Name: | C2: =1-E2-F2-G2-H2-I2-J2-K2-L2 -> 0.478 | E2: ='Sunday WK1 (1)'!E2 -> 0.099 | F2: ='Sunday WK1 (1)'!F2 -> 0 | G2: ='Sunday WK1 (1)'!G2 -> 0 | H2: ='Sunday WK1 (1)'!H2 -> 0 | I2: ='Sunday WK1 (1)'!I2 -> 0.159 | J2: ='Sunday WK1 (1)'!J2 -> 0.122 | K2: ='Sunday WK1 (1)'!$K$2 -> 0.142 | L2: ='Sunday WK1 (1)'!L2 -> 0 | N2: =SUM(C2:M2) -> 1
B3: SHANNON | C3: =C2*$N$3 -> 0 | E3: =E2*$N$3 -> 0 | F3: =F2*$N$3 -> 0 | G3: =G2*$N$3 -> 0 | H3: =H2*$N$3 -> 0 | I3: =I2*$N$3 -> 0 | J3: =J2*$N$3 -> 0 | K3: =K2*$N$3 -> 0 | L3: =L2*$N$3 -> 0
A4: Receiving Date: | B4: ='Sunday WK1 (1)'!B4+1 -> 46195
A5: Invoice Number | B5: Supplier Name | C5: Grocery Purchases | D5: Tobacco Purchases | E5: Meat Purchases | F5: Bakery Purchases | G5: Bakery In Store | H5: Deli Purchases | I5: Produce Purchases | J5: Produce Shrink | K5: Dairy Purchases | L5: Pharmacy Purchases | M5: GST | N5: Total Invoice**
A6: 9597126 | B6: THE GROCERY PEOPLE | C6: =N6-D6-E6-F6-G6-H6-I6-J6-K6-L6-M6-D60-E60-F60-G60-H60-I60-J60-K60-L60-C60 -> 0 | K6: -35.02 | N6: -35.02 | O6: DAMAGED - INTL DELIGHT
A7: 9597117 | B7: THE GROCERY PEOPLE | C7: =N7-D7-E7-F7-G7-H7-I7-J7-K7-L7-M7-D61-E61-F61-G61-H61-I61-J61-K61-L61-C61 -> 0 | K7: -20.34 | N7: -20.34 | O7: DAMAGED - SPARKS EGGS
A8: 9598881 | B8: THE GROCERY PEOPLE | C8: =N8-D8-E8-F8-G8-H8-I8-J8-K8-L8-M8-D62-E62-F62-G62-H62-I62-J62-K62-L62-C62 -> 0 | K8: -22.33 | N8: -22.33 | O8: SHORTED - DANONE OIKOS
A9: 9598880 | B9: THE GROCERY PEOPLE | C9: =N9-D9-E9-F9-G9-H9-I9-J9-K9-L9-M9-D63-E63-F63-G63-H63-I63-J63-K63-L63-C63 -> 0 | K9: -62 | M9: 0 | N9: -62 | O9: SHORTED - CG XL EGGS
A10: 52933821006 | B10: COCA COLA CANADA BOTTLING | C10: =N10-D10-E10-F10-G10-H10-I10-J10-K10-L10-M10-D64-E64-F64-G64-H64-I64-J64-K64-L64-C64 -> 5954.68 | M10: 247.06 | N10: 6201.74
A11: 53927300 | B11: PEPSICO | C11: =N11-D11-E11-F11-G11-H11-I11-J11-K11-L11-M11-D65-E65-F65-G65-H65-I65-J65-K65-L65-C65 -> 6843.37 | M11: 192.53 | N11: 7035.9
A12: 32698 | B12: NELLA WEST | C12: =N12-D12-E12-F12-G12-H12-I12-J12-K12-L12-M12-D66-E66-F66-G66-H66-I66-J66-K66-L66-C66 -> 3172.5 | M12: 158.63 | N12: 3331.13
A13: 2306 | B13: NELLA WEST | C13: =N13-D13-E13-F13-G13-H13-I13-J13-K13-L13-M13-D67-E67-F67-G67-H67-I67-J67-K67-L67-C67 -> -19.41 | M13: -0.97 | N13: -20.38
A14: 126301 | B14: ITALIAN BAKERY | C14: =N14-D14-E14-F14-G14-H14-I14-J14-K14-L14-M14-D68-E68-F68-G68-H68-I68-J68-K68-L68-C68 -> 290.94 | N14: 290.94
A15: 2031031154 | B15: RED BULL CANADA | C15: =N15-D15-E15-F15-G15-H15-I15-J15-K15-L15-M15-D69-E69-F69-G69-H69-I69-J69-K69-L69-C69 -> 8801.4 | M15: 422.34 | N15: 9223.74
A16: 2031031155 | B16: RED BULL CANADA | C16: =N16-D16-E16-F16-G16-H16-I16-J16-K16-L16-M16-D70-E70-F70-G70-H70-I70-J70-K70-L70-C70 -> -4801.8 | M16: -231.81 | N16: -5033.61
A17: 82849759 | B17: OLD DUTCH FOODS | C17: =N17-D17-E17-F17-G17-H17-I17-J17-K17-L17-M17-D71-E71-F71-G71-H71-I71-J71-K71-L71-C71 -> 463.47 | M17: 13.63 | N17: 477.1
A18: 82849760 | B18: OLD DUTCH FOODS | C18: =N18-D18-E18-F18-G18-H18-I18-J18-K18-L18-M18-D72-E72-F72-G72-H72-I72-J72-K72-L72-C72 -> -76.48 | M18: -3.82 | N18: -80.3
A19: 226650717304 | B19: CANADA BREAD COMPANY | C19: =N19-D19-E19-F19-G19-H19-I19-J19-K19-L19-M19-D73-E73-F73-G73-H73-I73-J73-K73-L73-C73 -> 1238.29 | M19: 1.87 | N19: 1240.16
A20: 226650717305 | B20: CANADA BREAD COMPANY | C20: =N20-D20-E20-F20-G20-H20-I20-J20-K20-L20-M20-D74-E74-F74-G74-H74-I74-J74-K74-L74-C74 -> -318.43 | N20: -318.43
A21: 00020604 | B21: SEVEN SEAS FISH CO | C21: =N21-D21-E21-F21-G21-H21-I21-J21-K21-L21-M21-D75-E75-F75-G75-H75-I75-J75-K75-L75-C75 -> 388 | N21: 388
A22: 91205735 | B22: FRITO LAY CANADA VENDING | C22: =N22-D22-E22-F22-G22-H22-I22-J22-K22-L22-M22-D76-E76-F76-G76-H76-I76-J76-K76-L76-C76 -> 3014.44 | M22: 149.27 | N22: 3163.71
A23: 9501286 | B23: RECALL CLAIM | C23: =N23-D23-E23-F23-G23-H23-I23-J23-K23-L23-M23-D77-E77-F77-G77-H77-I77-J77-K77-L77-C77 -> -37.2 | N23: -37.2
C24: =N24-D24-E24-F24-G24-H24-I24-J24-K24-L24-M24-D78-E78-F78-G78-H78-I78-J78-K78-L78-C78 -> 0
C25: =N25-D25-E25-F25-G25-H25-I25-J25-K25-L25-M25-D79-E79-F79-G79-H79-I79-J79-K79-L79-C79 -> 0
C26: =N26-D26-E26-F26-G26-H26-I26-J26-K26-L26-M26-D80-E80-F80-G80-H80-I80-J80-K80-L80-C80 -> 0
C27: =N27-D27-E27-F27-G27-H27-I27-J27-K27-L27-M27-D81-E81-F81-G81-H81-I81-J81-K81-L81-C81 -> 0
C28: =N28-D28-E28-F28-G28-H28-I28-J28-K28-L28-M28-D82-E82-F82-G82-H82-I82-J82-K82-L82-C82 -> 0
C29: =N29-D29-E29-F29-G29-H29-I29-J29-K29-L29-M29-D83-E83-F83-G83-H83-I83-J83-K83-L83-C83 -> 0
C30: =N30-D30-E30-F30-G30-H30-I30-J30-K30-L30-M30-D84-E84-F84-G84-H84-I84-J84-K84-L84-C84 -> 0
C31: =N31-D31-E31-F31-G31-H31-I31-J31-K31-L31-M31-D85-E85-F85-G85-H85-I85-J85-K85-L85-C85 -> 0
C32: =N32-D32-E32-F32-G32-H32-I32-J32-K32-L32-M32-D86-E86-F86-G86-H86-I86-J86-K86-L86-C86 -> 0
C33: =N33-D33-E33-F33-G33-H33-I33-J33-K33-L33-M33-D87-E87-F87-G87-H87-I87-J87-K87-L87-C87 -> 0
C34: =N34-D34-E34-F34-G34-H34-I34-J34-K34-L34-M34-D88-E88-F88-G88-H88-I88-J88-K88-L88-C88 -> 0
C35: =N35-D35-E35-F35-G35-H35-I35-J35-K35-L35-M35-D89-E89-F89-G89-H89-I89-J89-K89-L89-C89 -> 0
... C55: =N55-D55-E55-F55-G55-H55-I55-J55-K55-L55-M55-D109-E109-F109-G109-H109-I109-J109-K109-L109-C109 -> 0
A56: Freight | B56: THE GROCERY PEOPLE | C56: =C3 -> 0 | E56: =E3 -> 0 | F56: =F3 -> 0 | G56: =G3 -> 0 | H56: =H3 -> 0 | I56: =I3 -> 0 | J56: =J3 -> 0 | K56: =K3 -> 0 | L56: =L3 -> 0 | N56: =SUM(C56:M56)+SUM(C118:J118) -> 0
A57: Department Totals | C57: =SUM(C6:C56) -> 24913.77 | D57: =SUM(D6:D56) -> 0 | E57: =SUM(E6:E56) -> 0 | F57: =SUM(F6:F56) -> 0 | G57: =SUM(G6:G56) -> 0 | H57: =SUM(H6:H56) -> 0 | I57: =SUM(I6:I56) -> 0 | J57: =SUM(J6:J56) -> 0 | ... N57: =SUM(N6:N56) -> 25722.81
N58: =IF(SUM(N6:N56)=SUM(C57:M57)+SUM(D110:L110),"","Sum error")
A59: =A5 -> Invoice Number | B59: =B5 -> Supplier Name | C59: Grocery Supplies | D59: Tobacco Supplies | E59: Meat Supplies | F59: Bakery Supplies | G59: B.In store Supplies | H59: Deli Supplies | I59: Produce Supplies | K59: Dairy Supplies | L59: Pharmacy Supplies
...

Sheet Tuesday WK1 (3)
B1: Freight | C1: Grocery | E1: Meat | F1: Bakery | G1: Bake off | H1: Deli | I1: Produce | J1: Produce Shrink | K1: Dairy | L1: Pharmacy | M1: Receiving Totals | N1: Total
B2: Name: | C2: ='Sunday WK1 (1)'!C2 -> 0.478 | E2: ='Sunday WK1 (1)'!E2 -> 0.099 | F2: ='Sunday WK1 (1)'!F2 -> 0 | G2: ='Sunday WK1 (1)'!G2 -> 0 | H2: ='Sunday WK1 (1)'!H2 -> 0 | I2: ='Sunday WK1 (1)'!I2 -> 0.159 | J2: ='Sunday WK1 (1)'!J2 -> 0.122 | K2: ='Sunday WK1 (1)'!$K$2 -> 0.142 | L2: ='Sunday WK1 (1)'!L2 -> 0 | N2: =SUM(C2:M2) -> 1
B3: SHANNON | C3: =C2*$N$3 -> 136.79882 | E3: =E2*$N$3 -> 28.33281 | F3: =F2*$N$3 -> 0 | G3: =G2*$N$3 -> 0 | H3: =H2*$N$3 -> 0 | I3: =I2*$N$3 -> 45.50421 | J3: =J2*$N$3 -> 34.91518 | K3: =K2*$N$3 -> 40.63898 | L3: =L2*$N$3 -> 0 | N3: 286.19
A4: Receiving Date: | B4: ='Monday WK1 (2)'!B4+1 -> 46196
A5: Invoice Number | B5: Supplier Name | C5: Grocery Purchases | D5: Tobacco Purchases | E5: Meat Purchases | F5: Bakery Purchases | G5: Bakery In Store | H5: Deli Purchases | I5: Produce Purchases | J5: Produce Shrink | K5: Dairy Purchases | L5: Pharmacy Purchases | M5: GST | N5: Total Invoice**
A6: 4003658983 | B6: SAPUTO DAIRY PRODUCTS | C6: =N6-D6-E6-F6-G6-H6-I6-J6-K6-L6-M6-D60-E60-F60-G60-H60-I60-J60-K60-L60-C60 -> -1.0913492e-13 | K6: 2872.12 | M6: 0.37 | N6: 2872.49
A7: 4003658984 | B7: SAPUTO DAIRY PRODUCTS | C7: =N7-D7-E7-F7-G7-H7-I7-J7-K7-L7-M7-D61-E61-F61-G61-H61-I61-J61-K61-L61-C61 -> 0 | K7: 27.3 | N7: 27.3
A8: 6651868 | B8: THE GROCERY PEOPLE | C8: =N8-D8-E8-F8-G8-H8-I8-J8-K8-L8-M8-D62-E62-F62-G62-H62-I62-J62-K62-L62-C62 -> 0 | E8: 3583.6 | N8: 3583.6
A9: 6651869 | B9: THE GROCERY PEOPLE | C9: =N9-D9-E9-F9-G9-H9-I9-J9-K9-L9-M9-D63-E63-F63-G63-H63-I63-J63-K63-L63-C63 -> 0 | E9: 868.06 | N9: 868.06
A10: 6652458 | B10: THE GROCERY PEOPLE | C10: =N10-D10-E10-F10-G10-H10-I10-J10-K10-L10-M10-D64-E64-F64-G64-H64-I64-J64-K64-L64-C64 -> 0 | E10: 468.47 | N10: 468.47
A11: 6652237 | B11: THE GROCERY PEOPLE | C11: =N11-D11-E11-F11-G11-H11-I11-J11-K11-L11-M11-D65-E65-F65-G65-H65-I65-J65-K65-L65-C65 -> 0 | E11: 40.37 | N11: 40.37
A12: 6654306 | B12: THE GROCERY PEOPLE | C12: =N12-D12-E12-F12-G12-H12-I12-J12-K12-L12-M12-D66-E66-F66-G66-H66-I66-J66-K66-L66-C66 -> 1461.28 | E12: 67.6 | N12: 1528.88
A13: 6654307 | B13: THE GROCERY PEOPLE | C13: =N13-D13-E13-F13-G13-H13-I13-J13-K13-L13-M13-D67-E67-F67-G67-H67-I67-J67-K67-L67-C67 -> 53.56 | N13: 53.56
A14: 6655847 | B14: THE GROCERY PEOPLE | C14: =N14-D14-E14-F14-G14-H14-I14-J14-K14-L14-M14-D68-E68-F68-G68-H68-I68-J68-K68-L68-C68 -> 0 | K14: 238.18 | N14: 238.18
A15: 6655848 | B15: THE GROCERY PEOPLE | C15: =N15-D15-E15-F15-G15-H15-I15-J15-K15-L15-M15-D69-E69-F69-G69-H69-I69-J69-K69-L69-C69 -> 0 | K15: 17.67 | N15: 17.67
A16: 6652880 | B16: THE GROCERY PEOPLE | C16: =N16-D16-E16-F16-G16-H16-I16-J16-K16-L16-M16-D70-E70-F70-G70-H70-I70-J70-K70-L70-C70 -> 17.82 | N16: 17.82
A17: 6654592 | B17: THE GROCERY PEOPLE | C17: =N17-D17-E17-F17-G17-H17-I17-J17-K17-L17-M17-D71-E71-F71-G71-H71-I71-J71-K71-L71-C71 -> 0 | K17: 61.96 | N17: 61.96
A18: 5628412 | B18: THE GROCERY PEOPLE | C18: =N18-D18-E18-F18-G18-H18-I18-J18-K18-L18-M18-D72-E72-F72-G72-H72-I72-J72-K72-L72-C72 -> 146.06 | N18: 146.06
A19: 5629476 | B19: THE GROCERY PEOPLE | C19: =N19-D19-E19-F19-G19-H19-I19-J19-K19-L19-M19-D73-E73-F73-G73-H73-I73-J73-K73-L73-C73 -> 751.57 | E19: 227.62 | N19: 979.19
A20: 5629477 | B20: THE GROCERY PEOPLE | C20: =N20-D20-E20-F20-G20-H20-I20-J20-K20-L20-M20-D74-E74-F74-G74-H74-I74-J74-K74-L74-C74 -> 2602.53 | K20: 81.23 | N20: 2683.76
A21: 5629583 | B21: THE GROCERY PEOPLE | C21: =N21-D21-E21-F21-G21-H21-I21-J21-K21-L21-M21-D75-E75-F75-G75-H75-I75-J75-K75-L75-C75 -> 93.33 | K21: 1997.11 | N21: 2090.44
A22: 8240446 | B22: THE GROCERY PEOPLE | C22: =N22-D22-E22-F22-G22-H22-I22-J22-K22-L22-M22-D76-E76-F76-G76-H76-I76-J76-K76-L76-C76 -> 0 | E22: 912.24 | N22: 912.24
A23: 8240459 | B23: THE GROCERY PEOPLE | C23: =N23-D23-E23-F23-G23-H23-I23-J23-K23-L23-M23-D77-E77-F77-G77-H77-I77-J77-K77-L77-C77 -> 0 | E23: 574.25 | N23: 574.25
A24: 5629081 | B24: THE GROCERY PEOPLE | C24: =N24-D24-E24-F24-G24-H24-I24-J24-K24-L24-M24-D78-E78-F78-G78-H78-I78-J78-K78-L78-C78 -> 229.87 | E24: 2288.86 | N24: 2518.73
A25: 5628411 | B25: THE GROCERY PEOPLE | C25: =N25-D25-E25-F25-G25-H25-I25-J25-K25-L25-M25-D79-E79-F79-G79-H79-I79-J79-K79-L79-C79 -> 564.1 | N25: 564.1
A26: 5628458 | B26: THE GROCERY PEOPLE | C26: =N26-D26-E26-F26-G26-H26-I26-J26-K26-L26-M26-D80-E80-F80-G80-H80-I80-J80-K80-L80-C80 -> 107.9 | N26: 107.9
A27: 5628794 | B27: THE GROCERY PEOPLE | C27: =N27-D27-E27-F27-G27-H27-I27-J27-K27-L27-M27-D81-E81-F81-G81-H81-I81-J81-K81-L81-C81 -> 0 | K27: 4914.09 | N27: 4914.09
A28: 5629380 | B28: THE GROCERY PEOPLE | C28: =N28-D28-E28-F28-G28-H28-I28-J28-K28-L28-M28-D82-E82-F82-G82-H82-I82-J82-K82-L82-C82 -> 54.26 | N28: 54.26
A29: 5629381 | B29: THE GROCERY PEOPLE | C29: =N29-D29-E29-F29-G29-H29-I29-J29-K29-L29-M29-D83-E83-F83-G83-H83-I83-J83-K83-L83-C83 -> 23204.51 | N29: 23204.51
A30: 5629424 | B30: THE GROCERY PEOPLE | C30: =N30-D30-E30-F30-G30-H30-I30-J30-K30-L30-M30-D84-E84-F84-G84-H84-I84-J84-K84-L84-C84 -> 0 | E30: 40.21 | N30: 40.21
A31: 5629562 | B31: THE GROCERY PEOPLE | C31: =N31-D31-E31-F31-G31-H31-I31-J31-K31-L31-M31-D85-E85-F85-G85-H85-I85-J85-K85-L85-C85 -> 66.62 | K31: 1062.81 | N31: 1129.43
A32: 5630086 | B32: THE GROCERY PEOPLE | C32: =N32-D32-E32-F32-G32-H32-I32-J32-K32-L32-M32-D86-E86-F86-G86-H86-I86-J86-K86-L86-C86 -> 0 | N32: 0.01 | O32: PRODUCE SUPPLIES - POS MATERIAL HALOS BINS
A33: 5630111 | B33: THE GROCERY PEOPLE | C33: =N33-D33-E33-F33-G33-H33-I33-J33-K33-L33-M33-D87-E87-F87-G87-H87-I87-J87-K87-L87-C87 -> 0 | I33: 333.25 | N33: 333.25
A34: 5630112 | B34: THE GROCERY PEOPLE | C34: =N34-D34-E34-F34-G34-H34-I34-J34-K34-L34-M34-D88-E88-F88-G88-H88-I88-J88-K88-L88-C88 -> 0 | I34: 4529.83 | N34: 4529.83
A35: 5630113 | B35: THE GROCERY PEOPLE | C35: =N35-D35-E35-F35-G35-H35-I35-J35-K35-L35-M35-D89-E89-F89-G89-H89-I89-J89-K89-L89-C89 -> 0 | I35: 1286.71 | N35: 1286.71
A36: 117986 | B36: KENNELLI SPRINGS | C36: =N36-D36-E36-F36-G36-H36-I36-J36-K36-L36-M36-D90-E90-F90-G90-H90-I90-J90-K90-L90-C90 -> 205 | M36: 0.75 | N36: 205.75
A37: INV26-04375 | B37: CAPITAL FINE MEATS | C37: =N37-D37-E37-F37-G37-H37-I37-J37-K37-L37-M37-D91-E91-F91-G91-H91-I91-J91-K91-L91-C91 -> 0 | E37: 778.94 | N37: 778.94
A38: 91458496 | B38: FRITO LAY CANADA RETAIL | C38: =N38-D38-E38-F38-G38-H38-I38-J38-K38-L38-M38-D92-E92-F92-G92-H92-I92-J92-K92-L92-C92 -> 536.1 | M38: 24.04 | N38: 560.14
A39: 77683973 | B39: FRITO LAY CANADA RETAIL | C39: =N39-D39-E39-F39-G39-H39-I39-J39-K39-L39-M39-D93-E93-F93-G93-H93-I93-J93-K93-L93-C93 -> -102.01 | M39: -5.1 | N39: -107.11
A40: 7726174002 | B40: UNITED DISTRIBUTION NETWORK | C40: =N40-D40-E40-F40-G40-H40-I40-J40-K40-L40-M40-D94-E94-F94-G94-H94-I94-J94-K94-L94-C94 -> 2309.78 | M40: 115.49 | N40: 2425.27
...

Sheet Wednesday WK1 (4)
B1: Freight | C1: Grocery | E1: Meat | F1: Bakery | G1: Bake off | H1: Deli | I1: Produce | J1: Produce Shrink | K1: Dairy | L1: Pharmacy | M1: Receiving Totals | N1: Total
B2: Name: | C2: ='Sunday WK1 (1)'!C2 -> 0.478 | E2: ='Sunday WK1 (1)'!E2 -> 0.099 | F2: ='Sunday WK1 (1)'!F2 -> 0 | G2: ='Sunday WK1 (1)'!G2 -> 0 | H2: ='Sunday WK1 (1)'!H2 -> 0 | I2: ='Sunday WK1 (1)'!I2 -> 0.159 | J2: ='Sunday WK1 (1)'!J2 -> 0.122 | K2: ='Sunday WK1 (1)'!$K$2 -> 0.142 | L2: ='Sunday WK1 (1)'!L2 -> 0 | N2: =SUM(C2:M2) -> 1
B3: SHANNON | C3: =C2*$N$3 -> 81.56114 | E3: =E2*$N$3 -> 16.89237 | F3: =F2*$N$3 -> 0 | G3: =G2*$N$3 -> 0 | H3: =H2*$N$3 -> 0 | I3: =I2*$N$3 -> 27.13017 | J3: =J2*$N$3 -> 20.81686 | K3: =K2*$N$3 -> 24.22946 | L3: =L2*$N$3 -> 0 | N3: 170.63
A4: Receiving Date: | B4: ='Tuesday WK1 (3)'!B4+1 -> 46197
A5: Invoice Number | B5: Supplier Name | C5: Grocery Purchases | D5: Tobacco Purchases | E5: Meat Purchases | F5: Bakery Purchases | G5: Bakery In Store | H5: Deli Purchases | I5: Produce Purchases | J5: Produce Shrink | K5: Dairy Purchases | L5: Pharmacy Purchases | M5: GST | N5: Total Invoice**
A6: 5226135003 | B6: UNITED DISTRIBUTION NETWORK | C6: =N6-D6-E6-F6-G6-H6-I6-J6-K6-L6-M6-D62-E62-F62-G62-H62-I62-J62-K62-L62-C62 -> -40.52 | M6: -1.99 | N6: -42.51
A7: 2474287 | B7: UNFI CANADA | C7: =N7-D7-E7-F7-G7-H7-I7-J7-K7-L7-M7-D63-E63-F63-G63-H63-I63-J63-K63-L63-C63 -> 720.35 | M7: 36.02 | N7: 756.37
A8: 5226142003 | B8: UNITED DISTRIBUTION NETWORK | C8: =N8-D8-E8-F8-G8-H8-I8-J8-K8-L8-M8-D64-E64-F64-G64-H64-I64-J64-K64-L64-C64 -> -51.91 | M8: -2.59 | N8: -54.5
A9: 5226149002 | B9: UNITED DISTRIBUTION NETWORK | C9: =N9-D9-E9-F9-G9-H9-I9-J9-K9-L9-M9-D65-E65-F65-G65-H65-I65-J65-K65-L65-C65 -> -132.5 | M9: -6.63 | N9: -139.13
A10: 6597432A | B10: THE GROCERY PEOPLE | C10: =N10-D10-E10-F10-G10-H10-I10-J10-K10-L10-M10-D66-E66-F66-G66-H66-I66-J66-K66-L66-C66 -> 940.97 | N10: 940.97
A11: 9590413 | B11: THE GROCERY PEOPLE | C11: =N11-D11-E11-F11-G11-H11-I11-J11-K11-L11-M11-D67-E67-F67-G67-H67-I67-J67-K67-L67-C67 -> 0 | E11: -4498.38 | N11: -4498.38 | O11: SHORT SHIPPED INV #8193088
A12: 1809156 | B12: THE GROCERY PEOPLE | C12: =N12-D12-E12-F12-G12-H12-I12-J12-K12-L12-M12-D68-E68-F68-G68-H68-I68-J68-K68-L68-C68 -> -1159.95 | N12: -1159.95 | O12: MAY RECLAMATION
A13: 86528036 | B13: FRITO LAY CANADA | C13: =N13-D13-E13-F13-G13-H13-I13-J13-K13-L13-M13-D69-E69-F69-G69-H69-I69-J69-K69-L69-C69 -> -66.53 | N13: -66.53
A14: 86528546 | B14: FRITO LAY CANADA | C14: =N14-D14-E14-F14-G14-H14-I14-J14-K14-L14-M14-D70-E70-F70-G70-H70-I70-J70-K70-L70-C70 -> 33.16 | N14: 33.16
A15: 10003557263 | B15: SAPUTO DAIRY PRODUCTS | C15: =N15-D15-E15-F15-G15-H15-I15-J15-K15-L15-M15-D71-E71-F71-G71-H71-I71-J71-K71-L71-C71 -> 0 | K15: -42.89 | N15: -42.89
A16: CREDIT MEMO | B16: THE GROCERY PEOPLE | C16: =N16-D16-E16-F16-G16-H16-I16-J16-K16-L16-M16-D72-E72-F72-G72-H72-I72-J72-K72-L72-C72 -> -3527.47 | N16: -3527.47 | O16: CREDIT FOR MIS KEY ISSUE - LEANE ELASCHUK
A17: 82849776 | B17: OLD DUTCH FOODS | C17: =N17-D17-E17-F17-G17-H17-I17-J17-K17-L17-M17-D73-E73-F73-G73-H73-I73-J73-K73-L73-C73 -> 431.09 | M17: 21.55 | N17: 452.64
A18: 82849777 | B18: OLD DUTCH FOODS | C18: =N18-D18-E18-F18-G18-H18-I18-J18-K18-L18-M18-D74-E74-F74-G74-H74-I74-J74-K74-L74-C74 -> -35.42 | M18: -1.77 | N18: -37.19
A19: 371789 | B19: DPB BAKING COMPANY | C19: =N19-D19-E19-F19-G19-H19-I19-J19-K19-L19-M19-D75-E75-F75-G75-H75-I75-J75-K75-L75-C75 -> 11744.88 | M19: 587.25 | N19: 12332.13
C20: =N20-D20-E20-F20-G20-H20-I20-J20-K20-L20-M20-D76-E76-F76-G76-H76-I76-J76-K76-L76-C76 -> 0
C21: =N21-D21-E21-F21-G21-H21-I21-J21-K21-L21-M21-D77-E77-F77-G77-H77-I77-J77-K77-L77-C77 -> 0
C22: =N22-D22-E22-F22-G22-H22-I22-J22-K22-L22-M22-D78-E78-F78-G78-H78-I78-J78-K78-L78-C78 -> 0
C23: =N23-D23-E23-F23-G23-H23-I23-J23-K23-L23-M23-D79-E79-F79-G79-H79-I79-J79-K79-L79-C79 -> 0
C24: =N24-D24-E24-F24-G24-H24-I24-J24-K24-L24-M24-D80-E80-F80-G80-H80-I80-J80-K80-L80-C80 -> 0
C25: =N25-D25-E25-F25-G25-H25-I25-J25-K25-L25-M25-D81-E81-F81-G81-H81-I81-J81-K81-L81-C81 -> 0
C26: =N26-D26-E26-F26-G26-H26-I26-J26-K26-L26-M26-D82-E82-F82-G82-H82-I82-J82-K82-L82-C82 -> 0
C27: =N27-D27-E27-F27-G27-H27-I27-J27-K27-L27-M27-D83-E83-F83-G83-H83-I83-J83-K83-L83-C83 -> 0
C28: =N28-D28-E28-F28-G28-H28-I28-J28-K28-L28-M28-D84-E84-F84-G84-H84-I84-J84-K84-L84-C84 -> 0
C29: =N29-D29-E29-F29-G29-H29-I29-J29-K29-L29-M29-D85-E85-F85-G85-H85-I85-J85-K85-L85-C85 -> 0
C30: =N30-D30-E30-F30-G30-H30-I30-J30-K30-L30-M30-D86-E86-F86-G86-H86-I86-J86-K86-L86-C86 -> 0
C31: =N31-D31-E31-F31-G31-H31-I31-J31-K31-L31-M31-D87-E87-F87-G87-H87-I87-J87-K87-L87-C87 -> 0
... C49: =N49-D49-E49-F49-G49-H49-I49-J49-K49-L49-M49-D105-E105-F105-G105-H105-I105-J105-K105-L105-C105 -> 0
C50: =N50-D50-E50-F50-G50-H50-I50-J50-K50-L50-M50-D105-E105-F105-G105-H105-I105-J105-K105-L105-C105 -> 0
C51: =N51-D51-E51-F51-G51-H51-I51-J51-K51-L51-M51-D106-E106-F106-G106-H106-I106-J106-K106-L106-C106 -> 0
C52: =N52-D52-E52-F52-G52-H52-I52-J52-K52-L52-M52-D107-E107-F107-G107-H107-I107-J107-K107-L107-C107 -> 0
C53: =N53-D53-E53-F53-G53-H53-I53-J53-K53-L53-M53-D108-E108-F108-G108-H108-I108-J108-K108-L108-C108 -> 0
C54: =N54-D54-E54-F54-G54-H54-I54-J54-K54-L54-M54-D109-E109-F109-G109-H109-I109-J109-K109-L109-C109 -> 0
C55: =N55-D55-E55-F55-G55-H55-I55-J55-K55-L55-M55-D110-E110-F110-G110-H110-I110-J110-K110-L110-C110 -> 0
A56: Freight | B56: THE GROCERY PEOPLE | C56: =C3 -> 81.56114 | E56: =E3 -> 16.89237 | F56: =F3 -> 0 | G56: =G3 -> 0 | H56: =H3 -> 0 | I56: =I3 -> 27.13017 | J56: =J3 -> 20.81686 | K56: =K3 -> 24.22946 | L56: =L3 -> 0 | N56: =SUM(C56:M56)+SUM(C116:J116) -> 170.63 | O56: DEBIT MEMO - MISSING FUEL SURCHARGE
A57: Department Totals | C57: =SUM(C6:C56) -> 8937.7111 | D57: =SUM(D6:D56) -> 0 | E57: =SUM(E6:E56) -> -4481.4876 | F57: =SUM(F6:F56) -> 0 | G57: =SUM(G6:G56) -> 0 | H57: =SUM(H6:H56) -> 0 | I57: =SUM(I6:I56) -> 27.13017 | J57: =SUM(J6:J56) -> 20.81686 | ... M57: =SUM(M6:M56) -> 631.84 | N57: =SUM(C57:M57) -> 5117.35
...

Sheet Thursday WK1 (5)
B1: Freight | C1: Grocery | E1: Meat | F1: Bakery | G1: Bake off | H1: Deli | I1: Produce | J1: Produce Shrink | K1: Dairy | L1: Pharmacy | M1: Receiving Totals | N1: Total
B2: Name: | C2: ='Sunday WK1 (1)'!C2 -> 0.478 | E2: ='Sunday WK1 (1)'!E2 -> 0.099 | F2: ='Sunday WK1 (1)'!F2 -> 0 | G2: ='Sunday WK1 (1)'!G2 -> 0 | H2: ='Sunday WK1 (1)'!H2 -> 0 | I2: ='Sunday WK1 (1)'!I2 -> 0.159 | J2: ='Sunday WK1 (1)'!J2 -> 0.122 | K2: ='Sunday WK1 (1)'!$K$2 -> 0.142 | L2: ='Sunday WK1 (1)'!L2 -> 0 | N2: =SUM(C2:M2) -> 1
B3: SHANNON | C3: =C2*$N$3 -> 186.55384 | E3: =E2*$N$3 -> 38.63772 | F3: =F2*$N$3 -> 0 | G3: =G2*$N$3 -> 0 | H3: =H2*$N$3 -> 0 | I3: =I2*$N$3 -> 62.05452 | J3: =J2*$N$3 -> 47.61416 | K3: =K2*$N$3 -> 55.41976 | L3: =L2*$N$3 -> 0 | N3: 390.28
A4: Receiving Date: | B4: ='Wednesday WK1 (4)'!B4+1 -> 46198
A5: Invoice Number | B5: Supplier Name | C5: Grocery Purchases | D5: Tobacco Purchases | E5: Meat Purchases | F5: Bakery Purchases | G5: Bakery In Store | H5: Deli Purchases | I5: Produce Purchases | J5: Produce Shrink | K5: Dairy Purchases | L5: Pharmacy Purchases | M5: GST | N5: Total Invoice**
A6: 4003676429 | B6: SAPUTO DAIRY PRODUCTS | C6: =N6-D6-E6-F6-G6-H6-I6-J6-K6-L6-M6-D60-E60-F60-G60-H60-I60-J60-K60-L60-C60 -> 3.4561243e-13 | K6: 2353.22 | M6: 0.37 | N6: 2353.59
A7: 962372 | B7: HARVEST MEATS | C7: =N7-D7-E7-F7-G7-H7-I7-J7-K7-L7-M7-D61-E61-F61-G61-H61-I61-J61-K61-L61-C61 -> 0 | E7: 474.62 | N7: 474.62
A8: 962772 | B8: HARVEST MEATS | C8: =N8-D8-E8-F8-G8-H8-I8-J8-K8-L8-M8-D62-E62-F62-G62-H62-I62-J62-K62-L62-C62 -> 0 | E8: 230.43 | N8: 230.43
A9: 6657512 | B9: THE GROCERY PEOPLE | C9: =N9-D9-E9-F9-G9-H9-I9-J9-K9-L9-M9-D63-E63-F63-G63-H63-I63-J63-K63-L63-C63 -> 0 | E9: 2830.76 | N9: 2830.76
A10: 6656802 | B10: THE GROCERY PEOPLE | C10: =N10-D10-E10-F10-G10-H10-I10-J10-K10-L10-M10-D64-E64-F64-G64-H64-I64-J64-K64-L64-C64 -> 169.54 | E10: 49.3 | N10: 218.84
A11: 6658481 | B11: THE GROCERY PEOPLE | C11: =N11-D11-E11-F11-G11-H11-I11-J11-K11-L11-M11-D65-E65-F65-G65-H65-I65-J65-K65-L65-C65 -> 0 | E11: 40.28 | N11: 40.28
A12: 6658482 | B12: THE GROCERY PEOPLE | C12: =N12-D12-E12-F12-G12-H12-I12-J12-K12-L12-M12-D66-E66-F66-G66-H66-I66-J66-K66-L66-C66 -> 0 | E12: 244.1 | N12: 244.1
A13: 5630396 | B13: THE GROCERY PEOPLE | C13: =N13-D13-E13-F13-G13-H13-I13-J13-K13-L13-M13-D67-E67-F67-G67-H67-I67-J67-K67-L67-C67 -> 1381.38 | N13: 1381.38
A14: 5631184 | B14: THE GROCERY PEOPLE | C14: =N14-D14-E14-F14-G14-H14-I14-J14-K14-L14-M14-D68-E68-F68-G68-H68-I68-J68-K68-L68-C68 -> 1567.44 | N14: 1567.44
A15: 5631309 | B15: THE GROCERY PEOPLE | C15: =N15-D15-E15-F15-G15-H15-I15-J15-K15-L15-M15-D69-E69-F69-G69-H69-I69-J69-K69-L69-C69 -> 135.96 | N15: 135.96
A16: 5631563 | B16: THE GROCERY PEOPLE | C16: =N16-D16-E16-F16-G16-H16-I16-J16-K16-L16-M16-D70-E70-F70-G70-H70-I70-J70-K70-L70-C70 -> 0 | N16: 136.65 | O16: MEAT SUPPLIES - FOAM TRAYS, DIGI SCALE LABELS
A17: 5632090 | B17: THE GROCERY PEOPLE | C17: =N17-D17-E17-F17-G17-H17-I17-J17-K17-L17-M17-D71-E71-F71-G71-H71-I71-J71-K71-L71-C71 -> 23731.42 | N17: 23731.42
A18: 5632206 | B18: THE GROCERY PEOPLE | C18: =N18-D18-E18-F18-G18-H18-I18-J18-K18-L18-M18-D72-E72-F72-G72-H72-I72-J72-K72-L72-C72 -> 30.29 | K18: 3177.33 | N18: 3207.62
A19: 5632207 | B19: THE GROCERY PEOPLE | C19: =N19-D19-E19-F19-G19-H19-I19-J19-K19-L19-M19-D73-E73-F73-G73-H73-I73-J73-K73-L73-C73 -> 0 | K19: 153.82 | N19: 153.82
A20: 8241401 | B20: THE GROCERY PEOPLE | C20: =N20-D20-E20-F20-G20-H20-I20-J20-K20-L20-M20-D74-E74-F74-G74-H74-I74-J74-K74-L74-C74 -> 0 | E20: 784.48 | N20: 784.48
A21: 8241504 | B21: THE GROCERY PEOPLE | C21: =N21-D21-E21-F21-G21-H21-I21-J21-K21-L21-M21-D75-E75-F75-G75-H75-I75-J75-K75-L75-C75 -> 0 | E21: 543.46 | N21: 543.46
A22: 5630017 | B22: THE GROCERY PEOPLE | C22: =N22-D22-E22-F22-G22-H22-I22-J22-K22-L22-M22-D76-E76-F76-G76-H76-I76-J76-K76-L76-C76 -> 0 | E22: 80.09 | N22: 80.09
A23: 5631316 | B23: THE GROCERY PEOPLE | C23: =N23-D23-E23-F23-G23-H23-I23-J23-K23-L23-M23-D77-E77-F77-G77-H77-I77-J77-K77-L77-C77 -> 0 | E23: 4276.81 | N23: 4276.81
A24: 5631317 | B24: THE GROCERY PEOPLE | C24: =N24-D24-E24-F24-G24-H24-I24-J24-K24-L24-M24-D78-E78-F78-G78-H78-I78-J78-K78-L78-C78 -> 0 | E24: 413.52 | N24: 413.52
A25: 8241502 | B25: THE GROCERY PEOPLE | C25: =N25-D25-E25-F25-G25-H25-I25-J25-K25-L25-M25-D79-E79-F79-G79-H79-I79-J79-K79-L79-C79 -> 0 | E25: 74.95 | N25: 74.95
A26: 5629864 | B26: THE GROCERY PEOPLE | C26: =N26-D26-E26-F26-G26-H26-I26-J26-K26-L26-M26-D80-E80-F80-G80-H80-I80-J80-K80-L80-C80 -> 38.22 | N26: 38.22
A27: 5630018 | B27: THE GROCERY PEOPLE | C27: =N27-D27-E27-F27-G27-H27-I27-J27-K27-L27-M27-D81-E81-F81-G81-H81-I81-J81-K81-L81-C81 -> 2273.04 | N27: 2273.04
A28: 5630406 | B28: THE GROCERY PEOPLE | C28: =N28-D28-E28-F28-G28-H28-I28-J28-K28-L28-M28-D82-E82-F82-G82-H82-I82-J82-K82-L82-C82 -> 46.24 | N28: 46.24
A29: 5630539 | B29: THE GROCERY PEOPLE | C29: =N29-D29-E29-F29-G29-H29-I29-J29-K29-L29-M29-D83-E83-F83-G83-H83-I83-J83-K83-L83-C83 -> 476.46 | N29: 476.46
A30: 5630540 | B30: THE GROCERY PEOPLE | C30: =N30-D30-E30-F30-G30-H30-I30-J30-K30-L30-M30-D84-E84-F84-G84-H84-I84-J84-K84-L84-C84 -> 462.19 | N30: 462.19
A31: 5630541 | B31: THE GROCERY PEOPLE | C31: =N31-D31-E31-F31-G31-H31-I31-J31-K31-L31-M31-D85-E85-F85-G85-H85-I85-J85-K85-L85-C85 -> 560.1 | N31: 560.1
A32: 5630542 | B32: THE GROCERY PEOPLE | C32: =N32-D32-E32-F32-G32-H32-I32-J32-K32-L32-M32-D86-E86-F86-G86-H86-I86-J86-K86-L86-C86 -> 84 | N32: 84
A33: 5631315 | B33: THE GROCERY PEOPLE | C33: =N33-D33-E33-F33-G33-H33-I33-J33-K33-L33-M33-D87-E87-F87-G87-H87-I87-J87-K87-L87-C87 -> 6205.53 | N33: 6205.53
A34: 5631564 | B34: THE GROCERY PEOPLE | C34: =N34-D34-E34-F34-G34-H34-I34-J34-K34-L34-M34-D88-E88-F88-G88-H88-I88-J88-K88-L88-C88 -> 186.86 | N34: 186.86
A35: 5631565 | B35: THE GROCERY PEOPLE | C35: =N35-D35-E35-F35-G35-H35-I35-J35-K35-L35-M35-D89-E89-F89-G89-H89-I89-J89-K89-L89-C89 -> 573.36 | N35: 573.36
A36: 5631647 | B36: THE GROCERY PEOPLE | C36: =N36-D36-E36-F36-G36-H36-I36-J36-K36-L36-M36-D90-E90-F90-G90-H90-I90-J90-K90-L90-C90 -> 55.43 | N36: 55.43
A37: 5631732 | B37: THE GROCERY PEOPLE | C37: =N37-D37-E37-F37-G37-H37-I37-J37-K37-L37-M37-D91-E91-F91-G91-H91-I91-J91-K91-L91-C91 -> 98.46 | N37: 98.46
... A40: 5632195 | B40: THE GROCERY PEOPLE | C40: =N40-D40-E40-F40-G40-H40-I40-J40-K40-L40-M40-D94-E94-F94-G94-H94-I94-J94-K94-L94-C94 -> 244.08 | N40: 244.08
A41: 5632205 | B41: THE GROCERY PEOPLE | C41: =N41-D41-E41-F41-G41-H41-I41-J41-K41-L41-M41-D95-E95-F95-G95-H95-I95-J95-K95-L95-C95 -> 66.62 | K41: 1974.36 | N41: 2040.98
A42: 5631290 | B42: THE GROCERY PEOPLE | C42: =N42-D42-E42-F42-G42-H42-I42-J42-K42-L42-M42-D96-E96-F96-G96-H96-I96-J96-K96-L96-C96 -> 0 | I42: 12.81 | N42: 12.81
...

Sheet Friday WK1 (6)
B1: Freight | C1: Grocery | E1: Meat | F1: Bakery | G1: Bake off | H1: Deli | I1: Produce | J1: Produce Shrink | K1: Dairy | L1: Pharmacy | M1: Receiving Totals | N1: Total
B2: Name: | C2: ='Sunday WK1 (1)'!C2 -> 0.478 | E2: ='Sunday WK1 (1)'!E2 -> 0.099 | F2: ='Sunday WK1 (1)'!F2 -> 0 | G2: ='Sunday WK1 (1)'!G2 -> 0 | H2: ='Sunday WK1 (1)'!H2 -> 0 | I2: ='Sunday WK1 (1)'!I2 -> 0.159 | J2: ='Sunday WK1 (1)'!J2 -> 0.122 | K2: ='Sunday WK1 (1)'!$K$2 -> 0.142 | L2: ='Sunday WK1 (1)'!L2 -> 0 | N2: =SUM(C2:M2) -> 1
B3: SHANNON | C3: =C2*$N$3 -> 0 | E3: =E2*$N$3 -> 0 | F3: =F2*$N$3 -> 0 | G3: =G2*$N$3 -> 0 | H3: =H2*$N$3 -> 0 | I3: =I2*$N$3 -> 0 | J3: =J2*$N$3 -> 0 | K3: =K2*$N$3 -> 0 | L3: =L2*$N$3 -> 0
A4: Receiving Date: | B4: ='Thursday WK1 (5)'!$B$4+1 -> 46199
A5: Invoice Number | B5: Supplier Name | C5: Grocery Purchases | D5: Tobacco Purchases | E5: Meat Purchases | F5: Bakery Purchases | G5: Bakery In Store | H5: Deli Purchases | I5: Produce Purchases | J5: Produce Shrink | K5: Dairy Purchases | L5: Pharmacy Purchases | M5: GST | N5: Total Invoice**
A6: 2882617703 | B6: DIRECT PLUS FOOD GROUP | C6: =N6-D6-E6-F6-G6-H6-I6-J6-K6-L6-M6-D60-E60-F60-G60-H60-I60-J60-K60-L60-C60 -> 51.36 | N6: 51.36
A7: 2882617704 | B7: DIRECT PLUS FOOD GROUP | C7: =N7-D7-E7-F7-G7-H7-I7-J7-K7-L7-M7-D61-E61-F61-G61-H61-I61-J61-K61-L61-C61 -> 0 | E7: 1274.02 | M7: 5.5 | N7: 1279.52
A8: 2882617705 | B8: DIRECT PLUS FOOD GROUP | C8: =N8-D8-E8-F8-G8-H8-I8-J8-K8-L8-M8-D62-E62-F62-G62-H62-I62-J62-K62-L62-C62 -> 0 | E8: 63.84 | N8: 63.84
A9: 2882617706 | B9: DIRECT PLUS FOOD GROUP | C9: =N9-D9-E9-F9-G9-H9-I9-J9-K9-L9-M9-D63-E63-F63-G63-H63-I63-J63-K63-L63-C63 -> -34.24 | N9: -34.24
A10: 2034298473 | B10: RED BULL CANADA | C10: =N10-D10-E10-F10-G10-H10-I10-J10-K10-L10-M10-D64-E64-F64-G64-H64-I64-J64-K64-L64-C64 -> 5841.35 | M10: 280.68 | N10: 6122.03
A11: 3285617701 | B11: ARCTIC GLACIER | C11: =N11-D11-E11-F11-G11-H11-I11-J11-K11-L11-M11-D65-E65-F65-G65-H65-I65-J65-K65-L65-C65 -> 2203.2 | N11: 2203.2
A12: 82849789 | B12: OLD DUTCH FOODS | C12: =N12-D12-E12-F12-G12-H12-I12-J12-K12-L12-M12-D66-E66-F66-G66-H66-I66-J66-K66-L66-C66 -> -60.88 | M12: -3.04 | N12: -63.92
A13: 82849788 | B13: OLD DUTCH FOODS | C13: =N13-D13-E13-F13-G13-H13-I13-J13-K13-L13-M13-D67-E67-F67-G67-H67-I67-J67-K67-L67-C67 -> 709.17 | M13: 35.46 | N13: 744.63
A14: 92793699 | B14: FRITO LAY CANADA RETAIL | C14: =N14-D14-E14-F14-G14-H14-I14-J14-K14-L14-M14-D68-E68-F68-G68-H68-I68-J68-K68-L68-C68 -> 521.86 | M14: 26.11 | N14: 547.97
A15: 26808937 | B15: FRITO LAY CANADA RETAIL | C15: =N15-D15-E15-F15-G15-H15-I15-J15-K15-L15-M15-D69-E69-F69-G69-H69-I69-J69-K69-L69-C69 -> -9.89 | M15: -0.49 | N15: -10.38
A16: 80594 | B16: NUTRIFRESH WEST | C16: =N16-D16-E16-F16-G16-H16-I16-J16-K16-L16-M16-D70-E70-F70-G70-H70-I70-J70-K70-L70-C70 -> 917.92 | M16: 39.2 | N16: 957.12
C17: =N17-D17-E17-F17-G17-H17-I17-J17-K17-L17-M17-D71-E71-F71-G71-H71-I71-J71-K71-L71-C71 -> 0
C18: =N18-D18-E18-F18-G18-H18-I18-J18-K18-L18-M18-D72-E72-F72-G72-H72-I72-J72-K72-L72-C72 -> 0
C19: =N19-D19-E19-F19-G19-H19-I19-J19-K19-L19-M19-D73-E73-F73-G73-H73-I73-J73-K73-L73-C73 -> 0
C20: =N20-D20-E20-F20-G20-H20-I20-J20-K20-L20-M20-D74-E74-F74-G74-H74-I74-J74-K74-L74-C74 -> 0
C21: =N21-D21-E21-F21-G21-H21-I21-J21-K21-L21-M21-D75-E75-F75-G75-H75-I75-J75-K75-L75-C75 -> 0
C22: =N22-D22-E22-F22-G22-H22-I22-J22-K22-L22-M22-D76-E76-F76-G76-H76-I76-J76-K76-L76-C76 -> 0
C23: =N23-D23-E23-F23-G23-H23-I23-J23-K23-L23-M23-D77-E77-F77-G77-H77-I77-J77-K77-L77-C77 -> 0
C24: =N24-D24-E24-F24-G24-H24-I24-J24-K24-L24-M24-D78-E78-F78-G78-H78-I78-J78-K78-L78-C78 -> 0
C25: =N25-D25-E25-F25-G25-H25-I25-J25-K25-L25-M25-D79-E79-F79-G79-H79-I79-J79-K79-L79-C79 -> 0
C26: =N26-D26-E26-F26-G26-H26-I26-J26-K26-L26-M26-D80-E80-F80-G80-H80-I80-J80-K80-L80-C80 -> 0
C27: =N27-D27-E27-F27-G27-H27-I27-J27-K27-L27-M27-D81-E81-F81-G81-H81-I81-J81-K81-L81-C81 -> 0
C28: =N28-D28-E28-F28-G28-H28-I28-J28-K28-L28-M28-D82-E82-F82-G82-H82-I82-J82-K82-L82-C82 -> 0
... C55: =N55-D55-E55-F55-G55-H55-I55-J55-K55-L55-M55-D109-E109-F109-G109-H109-I109-J109-K109-L109-C109 -> 0
A56: Freight | B56: THE GROCERY PEOPLE | C56: =C3 -> 0 | E56: =E3 -> 0 | F56: =F3 -> 0 | G56: =G3 -> 0 | H56: =H3 -> 0 | I56: =I3 -> 0 | J56: =J3 -> 0 | K56: =K3 -> 0 | L56: =L3 -> 0 | N56: =SUM(C56:M56)+SUM(C118:J118) -> 0
A57: Department Totals | C57: =SUM(C6:C56) -> 10139.85 | D57: =SUM(D6:D56) -> 0 | E57: =SUM(E6:E56) -> 1337.86 | F57: =SUM(F6:F56) -> 0 | G57: =SUM(G6:G56) -> 0 | H57: =SUM(H6:H56) -> 0 | I57: =SUM(I6:I56) -> 0 | J57: =SUM(J6:J56) -> 0 | ... N57: =SUM(N6:N56) -> 11861.13
N58: =IF(SUM(N6:N56)=SUM(C57:M57)+SUM(D110:L110),"","Sum error")
A59: =A5 -> Invoice Number | B59: =B5 -> Supplier Name | C59: Grocery Supplies | D59: Tobacco Supplies | E59: Meat Supplies | F59: Bakery Supplies | G59: B.In store Supplies | H59: Deli Supplies | I59: Produce Supplies | K59: Dairy Supplies | L59: Pharmacy Supplies
A60: =A6 -> 2882617703 | B60: =B6 -> DIRECT PLUS FOOD GROUP
A61: =A7 -> 2882617704 | B61: =B7 -> DIRECT PLUS FOOD GROUP
A62: =A8 -> 2882617705 | B62: =B8 -> DIRECT PLUS FOOD GROUP
A63: =A9 -> 2882617706 | B63: =B9 -> DIRECT PLUS FOOD GROUP
A64: =A10 -> 2034298473 | B64: =B10 -> RED BULL CANADA
A65: =A11 -> 3285617701 | B65: =B11 -> ARCTIC GLACIER
A66: =A12 -> 82849789 | B66: =B12 -> OLD DUTCH FOODS
...

Sheet Saturday WK1 (7)
B1: Freight | C1: Grocery | E1: Meat | F1: Bakery | G1: Bake off | H1: Deli | I1: Produce | J1: Produce Shrink | K1: Dairy | L1: Pharmacy | M1: Receiving Totals | N1: Total
B2: Name: | C2: ='Sunday WK1 (1)'!C2 -> 0.478 | E2: ='Sunday WK1 (1)'!E2 -> 0.099 | F2: ='Sunday WK1 (1)'!F2 -> 0 | G2: ='Sunday WK1 (1)'!G2 -> 0 | H2: ='Sunday WK1 (1)'!H2 -> 0 | I2: ='Sunday WK1 (1)'!I2 -> 0.159 | J2: ='Sunday WK1 (1)'!J2 -> 0.122 | K2: ='Sunday WK1 (1)'!$K$2 -> 0.142 | L2: ='Sunday WK1 (1)'!L2 -> 0 | N2: =SUM(C2:M2) -> 1
B3: SHANNON | C3: =C2*$N$3 -> 0 | E3: =E2*$N$3 -> 0 | F3: =F2*$N$3 -> 0 | G3: =G2*$N$3 -> 0 | H3: =H2*$N$3 -> 0 | I3: =I2*$N$3 -> 0 | J3: =J2*$N$3 -> 0 | K3: =K2*$N$3 -> 0 | L3: =L2*$N$3 -> 0
A4: Receiving Date: | B4: ='Friday WK1 (6)'!$B$4+1 -> 46200
A5: Invoice Number | B5: Supplier Name | C5: Grocery Purchases | D5: Tobacco Purchases | E5: Meat Purchases | F5: Bakery Purchases | G5: Bakery In Store | H5: Deli Purchases | I5: Produce Purchases | J5: Produce Shrink | K5: Dairy Purchases | L5: Pharmacy Purchases | M5: GST | N5: Total Invoice**
A6: 126454 | B6: ITALIAN BAKERY | C6: =N6-D6-E6-F6-G6-H6-I6-J6-K6-L6-M6-D60-E60-F60-G60-H60-I60-J60-K60-L60-C60 -> 126.65 | N6: 126.65
C7: =N7-D7-E7-F7-G7-H7-I7-J7-K7-L7-M7-D61-E61-F61-G61-H61-I61-J61-K61-L61-C61 -> 0
C8: =N8-D8-E8-F8-G8-H8-I8-J8-K8-L8-M8-D62-E62-F62-G62-H62-I62-J62-K62-L62-C62 -> 0
C9: =N9-D9-E9-F9-G9-H9-I9-J9-K9-L9-M9-D63-E63-F63-G63-H63-I63-J63-K63-L63-C63 -> 0
C10: =N10-D10-E10-F10-G10-H10-I10-J10-K10-L10-M10-D64-E64-F64-G64-H64-I64-J64-K64-L64-C64 -> 0
C11: =N11-D11-E11-F11-G11-H11-I11-J11-K11-L11-M11-D65-E65-F65-G65-H65-I65-J65-K65-L65-C65 -> 0
C12: =N12-D12-E12-F12-G12-H12-I12-J12-K12-L12-M12-D66-E66-F66-G66-H66-I66-J66-K66-L66-C66 -> 0
C13: =N13-D13-E13-F13-G13-H13-I13-J13-K13-L13-M13-D67-E67-F67-G67-H67-I67-J67-K67-L67-C67 -> 0
C14: =N14-D14-E14-F14-G14-H14-I14-J14-K14-L14-M14-D68-E68-F68-G68-H68-I68-J68-K68-L68-C68 -> 0
C15: =N15-D15-E15-F15-G15-H15-I15-J15-K15-L15-M15-D69-E69-F69-G69-H69-I69-J69-K69-L69-C69 -> 0
C16: =N16-D16-E16-F16-G16-H16-I16-J16-K16-L16-M16-D70-E70-F70-G70-H70-I70-J70-K70-L70-C70 -> 0
C17: =N17-D17-E17-F17-G17-H17-I17-J17-K17-L17-M17-D71-E71-F71-G71-H71-I71-J71-K71-L71-C71 -> 0
C18: =N18-D18-E18-F18-G18-H18-I18-J18-K18-L18-M18-D72-E72-F72-G72-H72-I72-J72-K72-L72-C72 -> 0
... C55: =N55-D55-E55-F55-G55-H55-I55-J55-K55-L55-M55-D109-E109-F109-G109-H109-I109-J109-K109-L109-C109 -> 0
A56: Freight | B56: THE GROCERY PEOPLE | C56: =C3 -> 0 | E56: =E3 -> 0 | F56: =F3 -> 0 | G56: =G3 -> 0 | H56: =H3 -> 0 | I56: =I3 -> 0 | J56: =J3 -> 0 | K56: =K3 -> 0 | L56: =L3 -> 0 | N56: =SUM(C56:M56)+SUM(C118:J118) -> 0
A57: Department Totals | C57: =SUM(C6:C56) -> 126.65 | D57: =SUM(D6:D56) -> 0 | E57: =SUM(E6:E56) -> 0 | F57: =SUM(F6:F56) -> 0 | G57: =SUM(G6:G56) -> 0 | H57: =SUM(H6:H56) -> 0 | I57: =SUM(I6:I56) -> 0 | J57: =SUM(J6:J56) -> 0 | ... N57: =SUM(N6:N56) -> 126.65
N58: =IF(SUM(N6:N56)=SUM(C57:M57)+SUM(D110:L110),"","Sum error")
A59: =A5 -> Invoice Number | B59: =B5 -> Supplier Name | C59: Grocery Supplies | D59: Tobacco Supplies | E59: Meat Supplies | F59: Bakery Supplies | G59: B.In store Supplies | H59: Deli Supplies | I59: Produce Supplies | K59: Dairy Supplies | L59: Pharmacy Supplies
A60: =A6 -> 126454 | B60: =B6 -> ITALIAN BAKERY
A61: =A7 | B61: =B7
A62: =A8 | B62: =B8
A63: =A9 | B63: =B9
A64: =A10 | B64: =B10
A65: =A11 | B65: =B11
A66: =A12 | B66: =B12
A67: =A13 | B67: =B13
A68: =A14 | B68: =B14
A69: =A15 | B69: =B15
A70: =A16 | B70: =B16
A71: =A17 | B71: =B17
... A109: =A55 | B109: =B55
A110: =A57 -> Department Totals | C110: =SUM(C60:C109) -> 0 | D110: =SUM(D60:D109) -> 0 | E110: =SUM(E60:E109) -> 0 | F110: =SUM(F60:F109) -> 0 | G110: =SUM(G60:G109) -> 0 | H110: =SUM(H60:H109) -> 0 | I110: =SUM(I60:I109) -> 0 | J110: =SUM(J60:J109) -> 0 | ... L110: =SUM(L60:L109) -> 0

Sheet Sunday WK2 (8)
B1: Freight | C1: Grocery | E1: Meat | F1: Bakery | G1: Bake off | H1: Deli | I1: Produce | J1: Produce Shrink | K1: Dairy | L1: Pharmacy | M1: Receiving Totals | N1: Total
B2: Name: | C2: ='Sunday WK1 (1)'!C2 -> 0.478 | E2: ='Sunday WK1 (1)'!E2 -> 0.099 | F2: ='Sunday WK1 (1)'!F2 -> 0 | G2: ='Sunday WK1 (1)'!G2 -> 0 | H2: ='Sunday WK1 (1)'!H2 -> 0 | I2: ='Sunday WK1 (1)'!I2 -> 0.159 | J2: ='Sunday WK1 (1)'!J2 -> 0.122 | K2: ='Sunday WK1 (1)'!$K$2 -> 0.142 | L2: ='Sunday WK1 (1)'!L2 -> 0 | N2: =SUM(C2:M2) -> 1
B3: SHANNON | C3: =C2*$N$3 -> 166.28664 | E3: =E2*$N$3 -> 34.44012 | F3: =F2*$N$3 -> 0 | G3: =G2*$N$3 -> 0 | H3: =H2*$N$3 -> 0 | I3: =I2*$N$3 -> 55.31292 | J3: =J2*$N$3 -> 42.44136 | K3: =K2*$N$3 -> 49.39896 | L3: =L2*$N$3 -> 0 | N3: 347.88
A4: Receiving Date: | B4: ='Saturday WK1 (7)'!B4+1 -> 46201
A5: Invoice Number | B5: Supplier Name | C5: Grocery Purchases | D5: Tobacco Purchases | E5: Meat Purchases | F5: Bakery Purchases | G5: Bakery In Store | H5: Deli Purchases | I5: Produce Purchases | J5: Produce Shrink | K5: Dairy Purchases | L5: Pharmacy Purchases | M5: GST | N5: Total Invoice**
A6: 1003652120 | B6: SAPUTO DAIRY PRODUCTS | C6: =N6-D6-E6-F6-G6-H6-I6-J6-K6-L6-M6-D60-E60-F60-G60-H60-I60-J60-K60-L60-C60 -> 0 | K6: -22.87 | N6: -22.87
A7: 4003701372 | B7: SAPUTO DAIRY PRODUCTS | C7: =N7-D7-E7-F7-G7-H7-I7-J7-K7-L7-M7-D61-E61-F61-G61-H61-I61-J61-K61-L61-C61 -> 1.8207658e-14 | K7: 3683.33 | M7: 0.48 | N7: 3683.81
A8: 4003701374 | B8: SAPUTO DAIRY PRODUCTS | C8: =N8-D8-E8-F8-G8-H8-I8-J8-K8-L8-M8-D62-E62-F62-G62-H62-I62-J62-K62-L62-C62 -> 0 | K8: 243.86 | N8: 243.86
A9: 3280944 | B9: LILYDALE SOFINA FOODS | C9: =N9-D9-E9-F9-G9-H9-I9-J9-K9-L9-M9-D63-E63-F63-G63-H63-I63-J63-K63-L63-C63 -> 0 | E9: 200.05 | N9: 200.05
A10: 100351280 | B10: FREYBE GOURMET FOODS | C10: =N10-D10-E10-F10-G10-H10-I10-J10-K10-L10-M10-D64-E64-F64-G64-H64-I64-J64-K64-L64-C64 -> 0 | E10: 403.86 | N10: 403.86
A11: SO185965 | B11: STAR PRODUCE | C11: =N11-D11-E11-F11-G11-H11-I11-J11-K11-L11-M11-D65-E65-F65-G65-H65-I65-J65-K65-L65-C65 -> -1.7763568e-15 | I11: 250.1 | M11: 8.97 | N11: 259.07
A12: 6660239 | B12: THE GROCERY PEOPLE | C12: =N12-D12-E12-F12-G12-H12-I12-J12-K12-L12-M12-D66-E66-F66-G66-H66-I66-J66-K66-L66-C66 -> 0 | E12: 699.86 | N12: 699.86
A13: 6660588 | B13: THE GROCERY PEOPLE | C13: =N13-D13-E13-F13-G13-H13-I13-J13-K13-L13-M13-D67-E67-F67-G67-H67-I67-J67-K67-L67-C67 -> 0 | E13: 2571.86 | N13: 2571.86
A14: 6665623 | B14: THE GROCERY PEOPLE | C14: =N14-D14-E14-F14-G14-H14-I14-J14-K14-L14-M14-D68-E68-F68-G68-H68-I68-J68-K68-L68-C68 -> 0 | E14: 4774.68 | N14: 4774.68
A15: 6661029 | B15: THE GROCERY PEOPLE | C15: =N15-D15-E15-F15-G15-H15-I15-J15-K15-L15-M15-D69-E69-F69-G69-H69-I69-J69-K69-L69-C69 -> 0 | N15: 101.34 | O15: MEAT SUPPLIES - DIGISCALE LABELS
A16: 6662077 | B16: THE GROCERY PEOPLE | C16: =N16-D16-E16-F16-G16-H16-I16-J16-K16-L16-M16-D70-E70-F70-G70-H70-I70-J70-K70-L70-C70 -> 935.31 | E16: 41.99 | N16: 977.3
A17: 6663371 | B17: THE GROCERY PEOPLE | C17: =N17-D17-E17-F17-G17-H17-I17-J17-K17-L17-M17-D71-E71-F71-G71-H71-I71-J71-K71-L71-C71 -> 0 | N17: 484.98 | O17: STORE SUPPLIES - GARBAGE & WASTE ODOR CONT
A18: 5632856 | B18: THE GROCERY PEOPLE | C18: =N18-D18-E18-F18-G18-H18-I18-J18-K18-L18-M18-D72-E72-F72-G72-H72-I72-J72-K72-L72-C72 -> 10227.84 | N18: 10227.84
A19: 5632861 | B19: THE GROCERY PEOPLE | C19: =N19-D19-E19-F19-G19-H19-I19-J19-K19-L19-M19-D73-E73-F73-G73-H73-I73-J73-K73-L73-C73 -> 20.4 | N19: 20.4
A20: 5633291 | B20: THE GROCERY PEOPLE | C20: =N20-D20-E20-F20-G20-H20-I20-J20-K20-L20-M20-D74-E74-F74-G74-H74-I74-J74-K74-L74-C74 -> 0 | N20: 123.28 | O20: STORE SUPPLIES - 6.5" WHITE SPOONS
A21: 5634754 | B21: THE GROCERY PEOPLE | C21: =N21-D21-E21-F21-G21-H21-I21-J21-K21-L21-M21-D75-E75-F75-G75-H75-I75-J75-K75-L75-C75 -> 66.16 | N21: 66.16
A22: 5635177 | B22: THE GROCERY PEOPLE | C22: =N22-D22-E22-F22-G22-H22-I22-J22-K22-L22-M22-D76-E76-F76-G76-H76-I76-J76-K76-L76-C76 -> 1003.53 | N22: 1003.53
A23: 5635270 | B23: THE GROCERY PEOPLE | C23: =N23-D23-E23-F23-G23-H23-I23-J23-K23-L23-M23-D77-E77-F77-G77-H77-I77-J77-K77-L77-C77 -> 70.56 | N23: 70.56
A24: 5635433 | B24: THE GROCERY PEOPLE | C24: =N24-D24-E24-F24-G24-H24-I24-J24-K24-L24-M24-D78-E78-F78-G78-H78-I78-J78-K78-L78-C78 -> 2030.36 | N24: 2030.36
A25: 5635914 | B25: THE GROCERY PEOPLE | C25: =N25-D25-E25-F25-G25-H25-I25-J25-K25-L25-M25-D79-E79-F79-G79-H79-I79-J79-K79-L79-C79 -> 20659.39 | N25: 20659.39
A26: 5635916 | B26: THE GROCERY PEOPLE | C26: =N26-D26-E26-F26-G26-H26-I26-J26-K26-L26-M26-D80-E80-F80-G80-H80-I80-J80-K80-L80-C80 -> 2687.33 | N26: 2687.33
A27: 5636042 | B27: THE GROCERY PEOPLE | C27: =N27-D27-E27-F27-G27-H27-I27-J27-K27-L27-M27-D81-E81-F81-G81-H81-I81-J81-K81-L81-C81 -> 534.24 | N27: 534.24
A28: 5636044 | B28: THE GROCERY PEOPLE | C28: =N28-D28-E28-F28-G28-H28-I28-J28-K28-L28-M28-D82-E82-F82-G82-H82-I82-J82-K82-L82-C82 -> 70.5 | K28: 3088.08 | N28: 3158.58
A29: 5636045 | B29: THE GROCERY PEOPLE | C29: =N29-D29-E29-F29-G29-H29-I29-J29-K29-L29-M29-D83-E83-F83-G83-H83-I83-J83-K83-L83-C83 -> 0 | K29: 49.56 | N29: 49.56
A30: 8242570 | B30: THE GROCERY PEOPLE | C30: =N30-D30-E30-F30-G30-H30-I30-J30-K30-L30-M30-D84-E84-F84-G84-H84-I84-J84-K84-L84-C84 -> 0 | E30: 252.4 | N30: 252.4
A31: 8242976 | B31: THE GROCERY PEOPLE | C31: =N31-D31-E31-F31-G31-H31-I31-J31-K31-L31-M31-D85-E85-F85-G85-H85-I85-J85-K85-L85-C85 -> 0 | E31: 1286.43 | N31: 1286.43
A32: 8243386 | B32: THE GROCERY PEOPLE | C32: =N32-D32-E32-F32-G32-H32-I32-J32-K32-L32-M32-D86-E86-F86-G86-H86-I86-J86-K86-L86-C86 -> 0 | E32: 663.35 | N32: 663.35
A33: 8243603 | B33: THE GROCERY PEOPLE | C33: =N33-D33-E33-F33-G33-H33-I33-J33-K33-L33-M33-D87-E87-F87-G87-H87-I87-J87-K87-L87-C87 -> 0 | E33: 415.01 | N33: 415.01
A34: 5632862 | B34: THE GROCERY PEOPLE | C34: =N34-D34-E34-F34-G34-H34-I34-J34-K34-L34-M34-D88-E88-F88-G88-H88-I88-J88-K88-L88-C88 -> 0 | N34: 58.64 | O34: STORE SUPPLIES - STRETCH WRAP
A35: 5632970 | B35: THE GROCERY PEOPLE | C35: =N35-D35-E35-F35-G35-H35-I35-J35-K35-L35-M35-D89-E89-F89-G89-H89-I89-J89-K89-L89-C89 -> 108.15 | N35: 108.15
A36: 5633158 | B36: THE GROCERY PEOPLE | C36: =N36-D36-E36-F36-G36-H36-I36-J36-K36-L36-M36-D90-E90-F90-G90-H90-I90-J90-K90-L90-C90 -> 1188.3 | N36: 1188.3
A37: 5633948 | B37: THE GROCERY PEOPLE | C37: =N37-D37-E37-F37-G37-H37-I37-J37-K37-L37-M37-D91-E91-F91-G91-H91-I91-J91-K91-L91-C91 -> 114.66 | N37: 114.66
A38: 5634067 | B38: THE GROCERY PEOPLE | C38: =N38-D38-E38-F38-G38-H38-I38-J38-K38-L38-M38-D92-E92-F92-G92-H92-I92-J92-K92-L92-C92 -> 420.46 | N38: 420.46
A39: 5634483 | B39: THE GROCERY PEOPLE | C39: =N39-D39-E39-F39-G39-H39-I39-J39-K39-L39-M39-D93-E93-F93-G93-H93-I93-J93-K93-L93-C93 -> 281.94 | N39: 281.94
A40: 5635178 | B40: THE GROCERY PEOPLE | C40: =N40-D40-E40-F40-G40-H40-I40-J40-K40-L40-M40-D94-E94-F94-G94-H94-I94-J94-K94-L94-C94 -> 11.76 | N40: 11.76
...

Sheet Monday WK2 (9)
B1: Freight | C1: Grocery | E1: Meat | F1: Bakery | G1: Bake off | H1: Deli | I1: Produce | J1: Produce Shrink | K1: Dairy | L1: Pharmacy | M1: Receiving Totals | N1: Total
B2: Name: | C2: ='Sunday WK1 (1)'!C2 -> 0.478 | E2: ='Sunday WK1 (1)'!E2 -> 0.099 | F2: ='Sunday WK1 (1)'!F2 -> 0 | G2: ='Sunday WK1 (1)'!G2 -> 0 | H2: ='Sunday WK1 (1)'!H2 -> 0 | I2: ='Sunday WK1 (1)'!I2 -> 0.159 | J2: ='Sunday WK1 (1)'!J2 -> 0.122 | K2: ='Sunday WK1 (1)'!$K$2 -> 0.142 | L2: ='Sunday WK1 (1)'!L2 -> 0 | N2: =SUM(C2:M2) -> 1
B3: SHANNON | C3: =C2*$N$3 -> 0 | E3: =E2*$N$3 -> 0 | F3: =F2*$N$3 -> 0 | G3: =G2*$N$3 -> 0 | H3: =H2*$N$3 -> 0 | I3: =I2*$N$3 -> 0 | J3: =J2*$N$3 -> 0 | K3: =K2*$N$3 -> 0 | L3: =L2*$N$3 -> 0
A4: Receiving Date: | B4: ='Sunday WK2 (8)'!$B$4+1 -> 46202
A5: Invoice Number | B5: Supplier Name | C5: Grocery Purchases | D5: Tobacco Purchases | E5: Meat Purchases | F5: Bakery Purchases | G5: Bakery In Store | H5: Deli Purchases | I5: Produce Purchases | J5: Produce Shrink | K5: Dairy Purchases | L5: Pharmacy Purchases | M5: GST | N5: Total Invoice**
A6: 92578138 | B6: FRITO LAY CANADA VENDING | C6: =N6-D6-E6-F6-G6-H6-I6-J6-K6-L6-M6-D60-E60-F60-G60-H60-I60-J60-K60-L60-C60 -> 1727.85 | M6: 86.39 | N6: 1814.24
A7: 54132304 | B7: PEPSICO | C7: =N7-D7-E7-F7-G7-H7-I7-J7-K7-L7-M7-D61-E61-F61-G61-H61-I61-J61-K61-L61-C61 -> 2747.84 | M7: 121.75 | N7: 2869.59
A8: 54132303 | B8: PEPSICO | C8: =N8-D8-E8-F8-G8-H8-I8-J8-K8-L8-M8-D62-E62-F62-G62-H62-I62-J62-K62-L62-C62 -> 4446.06 | M8: 168.45 | N8: 4614.51
A9: 226650718099 | B9: CANADA BREAD COMPANY | C9: =N9-D9-E9-F9-G9-H9-I9-J9-K9-L9-M9-D63-E63-F63-G63-H63-I63-J63-K63-L63-C63 -> 1062.23 | N9: 1062.23
A10: 226650718001 | B10: CANADA BREAD COMPANY | C10: =N10-D10-E10-F10-G10-H10-I10-J10-K10-L10-M10-D64-E64-F64-G64-H64-I64-J64-K64-L64-C64 -> -180.32 | N10: -180.32
A11: 82849805 | B11: OLD DUTCH FOODS | C11: =N11-D11-E11-F11-G11-H11-I11-J11-K11-L11-M11-D65-E65-F65-G65-H65-I65-J65-K65-L65-C65 -> 262.61 | M11: 13.13 | N11: 275.74
A12: 126480 | B12: ITALIAN BAKERY | C12: =N12-D12-E12-F12-G12-H12-I12-J12-K12-L12-M12-D66-E66-F66-G66-H66-I66-J66-K66-L66-C66 -> 423.49 | N12: 423.49
A13: INV26-04514 | B13: CAPITAL FINE MEATS | C13: =N13-D13-E13-F13-G13-H13-I13-J13-K13-L13-M13-D67-E67-F67-G67-H67-I67-J67-K67-L67-C67 -> 0 | E13: 2041.15 | N13: 2041.15
C14: =N14-D14-E14-F14-G14-H14-I14-J14-K14-L14-M14-D68-E68-F68-G68-H68-I68-J68-K68-L68-C68 -> 0
C15: =N15-D15-E15-F15-G15-H15-I15-J15-K15-L15-M15-D69-E69-F69-G69-H69-I69-J69-K69-L69-C69 -> 0
C16: =N16-D16-E16-F16-G16-H16-I16-J16-K16-L16-M16-D70-E70-F70-G70-H70-I70-J70-K70-L70-C70 -> 0
C17: =N17-D17-E17-F17-G17-H17-I17-J17-K17-L17-M17-D71-E71-F71-G71-H71-I71-J71-K71-L71-C71 -> 0
C18: =N18-D18-E18-F18-G18-H18-I18-J18-K18-L18-M18-D72-E72-F72-G72-H72-I72-J72-K72-L72-C72 -> 0
C19: =N19-D19-E19-F19-G19-H19-I19-J19-K19-L19-M19-D73-E73-F73-G73-H73-I73-J73-K73-L73-C73 -> 0
C20: =N20-D20-E20-F20-G20-H20-I20-J20-K20-L20-M20-D74-E74-F74-G74-H74-I74-J74-K74-L74-C74 -> 0
C21: =N21-D21-E21-F21-G21-H21-I21-J21-K21-L21-M21-D75-E75-F75-G75-H75-I75-J75-K75-L75-C75 -> 0
C22: =N22-D22-E22-F22-G22-H22-I22-J22-K22-L22-M22-D76-E76-F76-G76-H76-I76-J76-K76-L76-C76 -> 0
C23: =N23-D23-E23-F23-G23-H23-I23-J23-K23-L23-M23-D77-E77-F77-G77-H77-I77-J77-K77-L77-C77 -> 0
C24: =N24-D24-E24-F24-G24-H24-I24-J24-K24-L24-M24-D78-E78-F78-G78-H78-I78-J78-K78-L78-C78 -> 0
C25: =N25-D25-E25-F25-G25-H25-I25-J25-K25-L25-M25-D79-E79-F79-G79-H79-I79-J79-K79-L79-C79 -> 0
... C55: =N55-D55-E55-F55-G55-H55-I55-J55-K55-L55-M55-D109-E109-F109-G109-H109-I109-J109-K109-L109-C109 -> 0
A56: Freight | B56: THE GROCERY PEOPLE | C56: =C3 -> 0 | E56: =E3 -> 0 | F56: =F3 -> 0 | G56: =G3 -> 0 | H56: =H3 -> 0 | I56: =I3 -> 0 | J56: =J3 -> 0 | K56: =K3 -> 0 | L56: =L3 -> 0 | N56: =SUM(C56:M56)+SUM(C118:J118) -> 0
A57: Department Totals | C57: =SUM(C6:C56) -> 10489.76 | D57: =SUM(D6:D56) -> 0 | E57: =SUM(E6:E56) -> 2041.15 | F57: =SUM(F6:F56) -> 0 | G57: =SUM(G6:G56) -> 0 | H57: =SUM(H6:H56) -> 0 | I57: =SUM(I6:I56) -> 0 | J57: =SUM(J6:J56) -> 0 | ... N57: =SUM(N6:N56) -> 12920.63
N58: =IF(SUM(N6:N56)=SUM(C57:M57)+SUM(D110:L110),"","Sum error")
A59: Invoice Number | B59: Supplier Name | C59: Grocery Supplies | D59: Tobacco Supplies | E59: Meat Supplies | F59: Bakery Supplies | G59: B.In store Supplies | H59: Deli Supplies | I59: Produce Supplies | K59: Dairy Supplies | L59: Pharmacy Supplies
A60: =A6 -> 92578138 | B60: =B6 -> FRITO LAY CANADA VENDING
A61: =A7 -> 54132304 | B61: =B7 -> PEPSICO
A62: =A8 -> 54132303 | B62: =B8 -> PEPSICO
A63: =A9 -> 226650718099 | B63: =B9 -> CANADA BREAD COMPANY
A64: =A10 -> 226650718001 | B64: =B10 -> CANADA BREAD COMPANY
A65: =A11 -> 82849805 | B65: =B11 -> OLD DUTCH FOODS
A66: =A12 -> 126480 | B66: =B12 -> ITALIAN BAKERY
A67: =A13 -> INV26-04514 | B67: =B13 -> CAPITAL FINE MEATS
A68: =A14 | B68: =B14
A69: =A15 | B69: =B15
...

Sheet Tuesday WK2 (10)
B1: Freight | C1: Grocery | E1: Meat | F1: Bakery | G1: Bake off | H1: Deli | I1: Produce | J1: Produce Shrink | K1: Dairy | L1: Pharmacy | M1: Receiving Totals | N1: Total
B2: Name: | C2: ='Sunday WK1 (1)'!C2 -> 0.478 | E2: ='Sunday WK1 (1)'!E2 -> 0.099 | F2: ='Sunday WK1 (1)'!F2 -> 0 | G2: ='Sunday WK1 (1)'!G2 -> 0 | H2: ='Sunday WK1 (1)'!H2 -> 0 | I2: ='Sunday WK1 (1)'!I2 -> 0.159 | J2: ='Sunday WK1 (1)'!J2 -> 0.122 | K2: ='Sunday WK1 (1)'!$K$2 -> 0.142 | L2: ='Sunday WK1 (1)'!L2 -> 0 | N2: =SUM(C2:M2) -> 1
B3: SHANNON | C3: =C2*$N$3 -> 197.46658 | E3: =E2*$N$3 -> 40.89789 | F3: =F2*$N$3 -> 0 | G3: =G2*$N$3 -> 0 | H3: =H2*$N$3 -> 0 | I3: =I2*$N$3 -> 65.68449 | J3: =J2*$N$3 -> 50.39942 | K3: =K2*$N$3 -> 58.66162 | L3: =L2*$N$3 -> 0 | N3: 413.11
A4: Receiving Date: | B4: ='Monday WK2 (9)'!$B$4+1 -> 46203
A5: Invoice Number | B5: Supplier Name | C5: Grocery Purchases | D5: Tobacco Purchases | E5: Meat Purchases | F5: Bakery Purchases | G5: Bakery In Store | H5: Deli Purchases | I5: Produce Purchases | J5: Produce Shrink | K5: Dairy Purchases | L5: Pharmacy Purchases | M5: GST | N5: Total Invoice**
A6: 32922 | B6: NELLA WEST | C6: =N6-D6-E6-F6-G6-H6-I6-J6-K6-L6-M6-D60-E60-F60-G60-H60-I60-J60-K60-L60-C60 -> 95.52 | M6: 4.78 | N6: 100.3
A7: 4003710022 | B7: SAPUTO DAIRY PRODUCTS | C7: =N7-D7-E7-F7-G7-H7-I7-J7-K7-L7-M7-D61-E61-F61-G61-H61-I61-J61-K61-L61-C61 -> 0 | K7: 2066.77 | M7: 0.5 | N7: 2067.27
A8: 4003710021 | B8: SAPUTO DAIRY PRODUCTS | C8: =N8-D8-E8-F8-G8-H8-I8-J8-K8-L8-M8-D62-E62-F62-G62-H62-I62-J62-K62-L62-C62 -> 0 | K8: 81.29 | N8: 81.29
A9: 6670111 | B9: THE GROCERY PEOPLE | C9: =N9-D9-E9-F9-G9-H9-I9-J9-K9-L9-M9-D63-E63-F63-G63-H63-I63-J63-K63-L63-C63 -> 256.15 | N9: 256.15
A10: 6670958 | B10: THE GROCERY PEOPLE | C10: =N10-D10-E10-F10-G10-H10-I10-J10-K10-L10-M10-D64-E64-F64-G64-H64-I64-J64-K64-L64-C64 -> 1355.42 | N10: 1355.42
A11: 6670959 | B11: THE GROCERY PEOPLE | C11: =N11-D11-E11-F11-G11-H11-I11-J11-K11-L11-M11-D65-E65-F65-G65-H65-I65-J65-K65-L65-C65 -> 37.32 | N11: 37.32
A12: 6671926 | B12: THE GROCERY PEOPLE | C12: =N12-D12-E12-F12-G12-H12-I12-J12-K12-L12-M12-D66-E66-F66-G66-H66-I66-J66-K66-L66-C66 -> 0 | K12: 142.13 | N12: 142.13
A13: 6671927 | B13: THE GROCERY PEOPLE | C13: =N13-D13-E13-F13-G13-H13-I13-J13-K13-L13-M13-D67-E67-F67-G67-H67-I67-J67-K67-L67-C67 -> 0 | K13: 18.47 | N13: 18.47
A14: 6671928 | B14: THE GROCERY PEOPLE | C14: =N14-D14-E14-F14-G14-H14-I14-J14-K14-L14-M14-D68-E68-F68-G68-H68-I68-J68-K68-L68-C68 -> 0 | E14: 119.66 | N14: 119.66
A15: 6669929 | B15: THE GROCERY PEOPLE | C15: =N15-D15-E15-F15-G15-H15-I15-J15-K15-L15-M15-D69-E69-F69-G69-H69-I69-J69-K69-L69-C69 -> 67.34 | N15: 67.34
A16: 5636178 | B16: THE GROCERY PEOPLE | C16: =N16-D16-E16-F16-G16-H16-I16-J16-K16-L16-M16-D70-E70-F70-G70-H70-I70-J70-K70-L70-C70 -> 918.9 | N16: 918.9
A17: 5636320 | B17: THE GROCERY PEOPLE | C17: =N17-D17-E17-F17-G17-H17-I17-J17-K17-L17-M17-D71-E71-F71-G71-H71-I71-J71-K71-L71-C71 -> 309.93 | N17: 309.93
A18: 5636542 | B18: THE GROCERY PEOPLE | C18: =N18-D18-E18-F18-G18-H18-I18-J18-K18-L18-M18-D72-E72-F72-G72-H72-I72-J72-K72-L72-C72 -> 603.08 | N18: 603.08
A19: 5637370 | B19: THE GROCERY PEOPLE | C19: =N19-D19-E19-F19-G19-H19-I19-J19-K19-L19-M19-D73-E73-F73-G73-H73-I73-J73-K73-L73-C73 -> 10914.84 | N19: 10914.84
A20: 5637433 | B20: THE GROCERY PEOPLE | C20: =N20-D20-E20-F20-G20-H20-I20-J20-K20-L20-M20-D74-E74-F74-G74-H74-I74-J74-K74-L74-C74 -> 1858.34 | N20: 1858.34
A21: 5637511 | B21: THE GROCERY PEOPLE | C21: =N21-D21-E21-F21-G21-H21-I21-J21-K21-L21-M21-D75-E75-F75-G75-H75-I75-J75-K75-L75-C75 -> 56.26 | K21: 2196.62 | N21: 2252.88
A22: 5637544 | B22: THE GROCERY PEOPLE | C22: =N22-D22-E22-F22-G22-H22-I22-J22-K22-L22-M22-D76-E76-F76-G76-H76-I76-J76-K76-L76-C76 -> 0 | K22: 678.96 | N22: 678.96
A23: 5636992 | B23: THE GROCERY PEOPLE | C23: =N23-D23-E23-F23-G23-H23-I23-J23-K23-L23-M23-D77-E77-F77-G77-H77-I77-J77-K77-L77-C77 -> 294.72 | E23: 2634.67 | N23: 2929.39
A24: 5636155 | B24: THE GROCERY PEOPLE | C24: =N24-D24-E24-F24-G24-H24-I24-J24-K24-L24-M24-D78-E78-F78-G78-H78-I78-J78-K78-L78-C78 -> 250.38 | N24: 250.38
A25: 5636457 | B25: THE GROCERY PEOPLE | C25: =N25-D25-E25-F25-G25-H25-I25-J25-K25-L25-M25-D79-E79-F79-G79-H79-I79-J79-K79-L79-C79 -> 0 | K25: 2354.24 | N25: 2354.24
A26: 5637011 | B26: THE GROCERY PEOPLE | C26: =N26-D26-E26-F26-G26-H26-I26-J26-K26-L26-M26-D80-E80-F80-G80-H80-I80-J80-K80-L80-C80 -> 175.35 | N26: 175.35
A27: 5637171 | B27: THE GROCERY PEOPLE | C27: =N27-D27-E27-F27-G27-H27-I27-J27-K27-L27-M27-D81-E81-F81-G81-H81-I81-J81-K81-L81-C81 -> 19618.78 | N27: 19618.78
A28: 5637215 | B28: THE GROCERY PEOPLE | C28: =N28-D28-E28-F28-G28-H28-I28-J28-K28-L28-M28-D82-E82-F82-G82-H82-I82-J82-K82-L82-C82 -> 208.1 | N28: 208.1
A29: 5637216 | B29: THE GROCERY PEOPLE | C29: =N29-D29-E29-F29-G29-H29-I29-J29-K29-L29-M29-D83-E83-F83-G83-H83-I83-J83-K83-L83-C83 -> 49.44 | N29: 49.44
A30: 5637995 | B30: THE GROCERY PEOPLE | C30: =N30-D30-E30-F30-G30-H30-I30-J30-K30-L30-M30-D84-E84-F84-G84-H84-I84-J84-K84-L84-C84 -> 0 | I30: 91.9 | N30: 91.9
A31: 5638018 | B31: THE GROCERY PEOPLE | C31: =N31-D31-E31-F31-G31-H31-I31-J31-K31-L31-M31-D85-E85-F85-G85-H85-I85-J85-K85-L85-C85 -> 0 | I31: 554.27 | N31: 554.27
A32: 5638025 | B32: THE GROCERY PEOPLE | C32: =N32-D32-E32-F32-G32-H32-I32-J32-K32-L32-M32-D86-E86-F86-G86-H86-I86-J86-K86-L86-C86 -> 0 | I32: 4267.34 | N32: 4267.34
A33: 5638041 | B33: THE GROCERY PEOPLE | C33: =N33-D33-E33-F33-G33-H33-I33-J33-K33-L33-M33-D87-E87-F87-G87-H87-I87-J87-K87-L87-C87 -> 0 | I33: 544.86 | N33: 544.86
A34: 6652917 | B34: FEDERATED CO-OPERATIVES | C34: =N34-D34-E34-F34-G34-H34-I34-J34-K34-L34-M34-D88-E88-F88-G88-H88-I88-J88-K88-L88-C88 -> 74.28 | N34: 74.28
A35: 6653196 | B35: FEDERATED CO-OPERATIVES | C35: =N35-D35-E35-F35-G35-H35-I35-J35-K35-L35-M35-D89-E89-F89-G89-H89-I89-J89-K89-L89-C89 -> 102.96 | N35: 102.96
A36: 6663764 | B36: FEDERATED CO-OPERATIVES | C36: =N36-D36-E36-F36-G36-H36-I36-J36-K36-L36-M36-D90-E90-F90-G90-H90-I90-J90-K90-L90-C90 -> 0 | N36: 44.69 | O36: STORE SUPPLIES - PENS, DBL TAPE, DRY ERASE
A37: 118511 | B37: KENNELLI SPRINGS | C37: =N37-D37-E37-F37-G37-H37-I37-J37-K37-L37-M37-D91-E91-F91-G91-H91-I91-J91-K91-L91-C91 -> 180 | M37: 0.75 | N37: 180.75
A38: 53048735061 | B38: COCA COLA CANADA BOTTLING | C38: =N38-D38-E38-F38-G38-H38-I38-J38-K38-L38-M38-D92-E92-F92-G92-H92-I92-J92-K92-L92-C92 -> 5865.9 | M38: 240.04 | N38: 6105.94
A39: 53048735062 | B39: COCA COLA CANADA BOTTLING | C39: =N39-D39-E39-F39-G39-H39-I39-J39-K39-L39-M39-D93-E93-F93-G93-H93-I93-J93-K93-L93-C93 -> 487.52 | M39: 22.19 | N39: 509.71
